Workbook
Name Matrice: OBJECTIFS!$C$45:$J$49

Sheet Cartouche
A5: CARTOUCHE
A7: DOCUMENT
A8: Référence | B8: MCC_S01_FEG-GRILLE BUSINESS HTLV_PRIMES AGENT-ACTIVITE
A9: Intitulé | B9: Grille de prime agent pour business hors télèvente
A10: Qui le remplit | B10: Chef de projet
A11: Quand le remplir | B11: avant le 10 de chaque mois
A12: A qui l'envoyer | B12: Directeur Général, Directeur des Opérations, DRH, Responsable Service Administratif RH
A13: Diffusion | B13: Prod et service paie
A16: TITRES | C16: DESIGNATION | E16: FORMAT
A17: Manager | C17: Nom du manager responsable de l'équipe | E17: Texte
A18: Opération | C18: Nom de l'opération ( Liste de choix) | E18: Texte
A19: Matricule | C19: Le matricule de l'agent | E19: alpha numérique
A20: Statut | C20: Liste de choix des différents statuts agent | E20: Texte
A21: Montant Cible | C21: Le montant total possible de la prime | E21: Monétaire
A22: Productivité | C22: Engloble 3 indicateurs quantitatifs de l'activité | E22: Nombre
A23: Qualité | C23: Englobe 2 indicateurs qualitatifs de l'activité | E23: Nombre
A24: Satisfaction client | C24: Le nombre de réclamations sur agent : Elément déclencheur de la prime) | E24: Nombre
A25: Heures produites | C25: les heures produites par l'agent en M-1 | E25: Nombre
A26: Assiduité, Comportement & Prorata | C26: Absences, retards, congés … etc. (Plus les mesures disciplinaires) | E26: Nombre
A27: Malus (en %) | C27: Taux de malus appliqué à la totalité de la prime | E27: Pourcentage
... A32: SOURCE PLANILICATION | C32: préciser si la planification des ressources se fait à notre niveau (interne) ou par le client | E32: Texte
A51: TABLEAU DE REVISION
A53: DATE | B53: VERSION | C53: NATURE MODIFICATION | D53: REDACTEUR | E53: VERIFICATEUR | F53: APPROBATEUR
A54: 40817 | B54: 1 | C54: Création | D54: Hamid ABDI | E54: FZ FATIH | F54: ZAKIA SLAOUI
A55: 40857 | B55: 2 | C55: Refonte de la grille | D55: Hamid ABDI | E55: FZ FATIH | F55: ZAKIA SLAOUI
A56: 44970 | B56: 3 | C56: Refonte de la grille: séparation des grilles activités téléventes et hors télévente | D56: FATIH FATIMA ZAHRA | E56: FATIH FATIMA ZAHRA | F56: FATIH FATIMA ZAHRA
A57: 45162 | B57: 4 | C57: Ajout ligne et correction formule de la proratisation de la prime de langue ajout notion planification interne et client | D57: FATIH FATIMA ZAHRA | E57: FATIH FATIMA ZAHRA | F57: FATIH FATIMA ZAHRA
A58: 45812 | B58: 5 | C58: Modification du malus réclamation client | D58: FATIH FATIMA ZAHRA | E58: FATIH FATIMA ZAHRA | F58: FATIH FATIMA ZAHRA

Sheet Variable
J1: Eléments déclencheurs = Réclamation client Agent | AH1: Règles d'assiduité | AR1: En cas d'execo on choisit par ordre
A2: Auteur EG: | J2: 1 réclamation client sur le mois | O2: Toute la prime est perdue | AH2: 1 Absence injustifiée ou 4 Retards | AM2: Moitié de la prime est perdue | AR2: 1 | AS2: Le statut le plus Haut
A3: Date émission EG: | AH3: 2 Absences injustifiée ou 8 Retards ou sanction | AM3: Totalité de la prime est perdue | AR3: 2 | AS3: La progression en nombre de points /mois précédent
AR4: 3 | AS4: Le nombre moyen de points du dernier trimestre
A5: SOURCE PLANILICATION | B5: Interne
A6: Noms prénoms | B6: Matricule | C6: Manager | D6: Opération | E6: Sanction disciplinaire | F6: Statut | H6: Montant Cible | J6: Productivité | V6: Qualité | AD6: Satisfaction client | AF6: Nb de points avant l'assiduité | AH6: Assiduité, Comportement & Prorata | AO6: Malus (en %) | AP6: Montant de la prime hors Super Bonus | AR6: =+IF(OBJECTIFS!G66="","BONUS 1",OBJECTIFS!G66) -> MISSION | AS6: =+IF(OBJECTIFS!G67="","BONUS 2",OBJECTIFS!G67) -> PRIME DE LANGUE | AT6: =+IF(OBJECTIFS!G68="","BONUS 3",OBJECTIFS!G68) -> BONUS 3 | AU6: =+IF(OBJECTIFS!G69="","BONUS 4",OBJECTIFS!G69) -> BONUS 4 | AV6: SUPER BONUS VENTES | AW6: Super Bonus | AY6: Montant Final de la prime | BA6: Nombre de points Final | BC6: L'agent du mois de l'activité
J7: =+OBJECTIFS!E5 -> KPI1 | K7: Objectif VS Statut | L7: Taux d'atteinte | M7: Nb de points | N7: =+OBJECTIFS!F5 -> KPI2 | O7: Objectif VS Statut | P7: Taux d'atteinte | Q7: Nb de points | R7: =+OBJECTIFS!G5 -> KPI3 | S7: Objectif VS Statut | T7: Taux d'atteinte | U7: Nb de points | V7: =+OBJECTIFS!H5 -> KPI4 | W7: Objectif VS Statut | X7: Taux d'atteinte | Y7: Nb de points | Z7: =+OBJECTIFS!I5 -> KPI5 | AA7: Objectif VS Statut | AB7: Taux d'atteinte | AC7: Nb de points | AD7: Réclamation client sur Agent | AH7: Heures produites | AI7: Abs injust. | AJ7: Retards | AK7: Abs just. | AL7: Congé payé + CSS (en j) | AM7: Nb de jours non travaillés | AN7: Nb de jours ouvrés du mois
M8: =OBJECTIFS!E4 -> 15 | Q8: =OBJECTIFS!F4 -> 27.5 | U8: =OBJECTIFS!G4 -> 27.5 | Y8: =OBJECTIFS!H4 -> 20 | AC8: =OBJECTIFS!I4 -> 10
H9: =IF(OR(D9="",F9="",A9=""),"",IF(E9="oui",0,IF(D9=OBJECTIFS!$C$45,VLOOKUP(F9,OBJECTIFS!$C$9:$D$11,2,FALSE),IF(D9=OBJECTIFS!$C$46,VLOOKUP(F9,OBJECTIFS!$C$16:$D$18,2,FALSE),IF(D9=OBJECTIFS!$C$47,VLOOKUP(F9,OBJECTIFS!$C$23:$D$25,2,FALSE),IF(D9=OBJECTIFS!$C$48,VLOOKUP(F9,OBJECTIFS!$C$30:$D$32,2,FALSE),IF(D9=OBJECTIFS!$C$49,VLOOKUP(F9,OBJECTIFS!$C$37:$D$39,2,FALSE)))))))) | K9: =IF(OR($A9="",$D9="",J9=""),"",SUMIFS(OBJECTIFS!E$9:E$39,OBJECTIFS!$A$9:$A$39,$D9,OBJECTIFS!$C$9:$C$39,$F9)) | L9: =IF(OR(AND($D9=OBJECTIFS!$B$6,OBJECTIFS!E$8="dmt"),AND($D9=OBJECTIFS!$B$13,OBJECTIFS!$E$15="dmt"),AND($D9=OBJECTIFS!$B$20,OBJECTIFS!$E$22="dmt"),AND($D9=OBJECTIFS!$B$27,OBJECTIFS!$E$29="dmt"),AND($D9=OBJECTIFS!$B$34,OBJECTIFS!$E$36="dmt"),AND($D9=OBJECTIFS!$B$6,OBJECTIFS!$E$8="taux de chute"),AND($D9=OBJECTIFS!$B$13,OBJECTIFS!$E$15="taux de chute"),AND($D9=OBJECTIFS!$B$20,OBJECTIFS!$E$22="taux de chute"),AND($D9=OBJECTIFS!$B$27,OBJECTIFS!$E$29="taux de chute"),AND($D9=OBJECTIFS!$B$34,OBJECTIFS!$E$36="taux de chute")),IFERROR(K9/J9,""),IFERROR(J9/K9,"")) | M9: =IFERROR(IF(OR(J9="",K9="",L9=""),0,IF(L9<OBJECTIFS!$E$56,0,IF(L9<OBJECTIFS!$G$56,M$8*OBJECTIFS!$F$60,IF(L9<OBJECTIFS!$I$56,M$8*OBJECTIFS!$H$60,M$8)))),0) -> 0 | O9: =IF(OR($A9="",$D9="",N9=""),"",SUMIFS(OBJECTIFS!F$9:F$39,OBJECTIFS!$A$9:$A$39,$D9,OBJECTIFS!$C$9:$C$39,$F9)) | P9: =IF(OR(AND($D9=OBJECTIFS!$B$6,OBJECTIFS!$F$8="dmt"),AND($D9=OBJECTIFS!$B$13,OBJECTIFS!$F$15="dmt"),AND($D9=OBJECTIFS!$B$20,OBJECTIFS!$F$22="dmt"),AND($D9=OBJECTIFS!$B$27,OBJECTIFS!$F$29="dmt"),AND($D9=OBJECTIFS!$B$34,OBJECTIFS!$F$36="dmt"),AND($D9=OBJECTIFS!$B$6,OBJECTIFS!$F$8="taux de chute"),AND($D9=OBJECTIFS!$B$13,OBJECTIFS!$F$15="taux de chute"),AND($D9=OBJECTIFS!$B$20,OBJECTIFS!$F$22="taux de chute"),AND($D9=OBJECTIFS!$B$27,OBJECTIFS!$F$29="taux de chute"),AND($D9=OBJECTIFS!$B$34,OBJECTIFS!$F$36="taux de chute")),IFERROR(O9/N9,""),IFERROR(N9/O9,"")) | Q9: =IFERROR(IF(OR(N9="",O9="",P9=""),0,IF(P9<OBJECTIFS!$E$56,0,IF(P9<OBJECTIFS!$G$56,Q$8*OBJECTIFS!$F$60,IF(P9<OBJECTIFS!$I$56,Q$8*OBJECTIFS!$H$60,Q$8)))),0) -> 0 | S9: =IF(OR($A9="",$D9="",R9=""),"",SUMIFS(OBJECTIFS!G$9:G$39,OBJECTIFS!$A$9:$A$39,$D9,OBJECTIFS!$C$9:$C$39,$F9)) | T9: =IF(OR(AND($D9=OBJECTIFS!$B$6,OBJECTIFS!G$8="dmt"),AND($D9=OBJECTIFS!$B$13,OBJECTIFS!$G$15="dmt"),AND($D9=OBJECTIFS!$B$20,OBJECTIFS!$G$22="dmt"),AND($D9=OBJECTIFS!$B$27,OBJECTIFS!$G$29="dmt"),AND($D9=OBJECTIFS!$B$34,OBJECTIFS!$G$36="dmt"),AND($D9=OBJECTIFS!$B$6,OBJECTIFS!$G$8="taux de chute"),AND($D9=OBJECTIFS!$B$13,OBJECTIFS!$G$15="taux de chute"),AND($D9=OBJECTIFS!$B$20,OBJECTIFS!$G$22="taux de chute"),AND($D9=OBJECTIFS!$B$27,OBJECTIFS!$G$29="taux de chute"),AND($D9=OBJECTIFS!$B$34,OBJECTIFS!$G$36="taux de chute")),IFERROR(S9/R9,""),IFERROR(R9/S9,"")) | U9: =IFERROR(IF(OR(R9="",S9="",T9=""),0,IF(T9<OBJECTIFS!$E$56,0,IF(T9<OBJECTIFS!$G$56,U$8*OBJECTIFS!$F$60,IF(T9<OBJECTIFS!$I$56,U$8*OBJECTIFS!$H$60,U$8)))),0) -> 0 | W9: =IF(OR($A9="",$D9="",V9=""),"",SUMIFS(OBJECTIFS!H$9:H$39,OBJECTIFS!$A$9:$A$39,$D9,OBJECTIFS!$C$9:$C$39,$F9)) | X9: =IF(OR(AND($D9=OBJECTIFS!$B$6,OBJECTIFS!H$8="dmt"),AND($D9=OBJECTIFS!$B$13,OBJECTIFS!$H$15="dmt"),AND($D9=OBJECTIFS!$B$20,OBJECTIFS!$H$22="dmt"),AND($D9=OBJECTIFS!$B$27,OBJECTIFS!$H$29="dmt"),AND($D9=OBJECTIFS!$B$34,OBJECTIFS!$H$36="dmt"),AND($D9=OBJECTIFS!$B$6,OBJECTIFS!$H$8="taux de chute"),AND($D9=OBJECTIFS!$B$13,OBJECTIFS!$H$15="taux de chute"),AND($D9=OBJECTIFS!$B$20,OBJECTIFS!$H$22="taux de chute"),AND($D9=OBJECTIFS!$B$27,OBJECTIFS!$H$29="taux de chute"),AND($D9=OBJECTIFS!$B$34,OBJECTIFS!$H$36="taux de chute")),IFERROR(W9/V9,""),IFERROR(V9/W9,"")) | Y9: =IFERROR(IF(OR(V9="",W9="",X9=""),0,IF(X9<OBJECTIFS!$E$56,0,IF(X9<OBJECTIFS!$G$56,Y$8*OBJECTIFS!$F$60,IF(X9<OBJECTIFS!$I$56,Y$8*OBJECTIFS!$H$60,Y$8)))),0) -> 0 | AA9: =IF(OR($A9="",$D9="",Z9=""),"",SUMIFS(OBJECTIFS!I$9:I$39,OBJECTIFS!$A$9:$A$39,$D9,OBJECTIFS!$C$9:$C$39,$F9)) | AB9: =IF(OR(AND($D9=OBJECTIFS!$B$6,OBJECTIFS!I$8="dmt"),AND($D9=OBJECTIFS!$B$13,OBJECTIFS!$I$15="dmt"),AND($D9=OBJECTIFS!$B$20,OBJECTIFS!$I$22="dmt"),AND($D9=OBJECTIFS!$B$27,OBJECTIFS!$I$29="dmt"),AND($D9=OBJECTIFS!$B$34,OBJECTIFS!$I$36="dmt"),AND($D9=OBJECTIFS!$B$6,OBJECTIFS!$I$8="taux de chute"),AND($D9=OBJECTIFS!$B$13,OBJECTIFS!$I$15="taux de chute"),AND($D9=OBJECTIFS!$B$20,OBJECTIFS!$I$22="taux de chute"),AND($D9=OBJECTIFS!$B$27,OBJECTIFS!$I$29="taux de chute"),AND($D9=OBJECTIFS!$B$34,OBJECTIFS!$I$36="taux de chute")),IFERROR(AA9/Z9,""),IFERROR(Z9/AA9,"")) | AC9: =IFERROR(IF(OR(Z9="",AA9="",AB9=""),0,IF(AB9<OBJECTIFS!$E$56,0,IF(AB9<OBJECTIFS!$G$56,AC$8*OBJECTIFS!$F$60,IF(AB9<OBJECTIFS!$I$56,AC$8*OBJECTIFS!$H$60,AC$8)))),0) -> 0 | AF9: =IF(AD9>=1,0,SUMIF($J$7:$AC$8,"Nb de points",$J9:$AC9)) -> 0 | AM9: =SUM(AK9:AL9,AI9) -> 0 | AN9: 22 | AO9: =IFERROR(IF(IF(OR(AI9>=2,AJ9>=8,AND(AI9=1,AJ9>=4)),0,IF(OR(AND(AI9=1,AJ9<4),AND(AI9=0,AJ9>=4,AJ9<8)),50%,100%))*(AN9-AM9)/AN9=0,-100%,IF(OR(AI9>=2,AJ9>=8,AND(AI9=1,AJ9>=4)),0,IF(OR(AND(AI9=1,AJ9<4),AND(AI9=0,AJ9>=4,AJ9<8)),50%,100%))*(AN9-AM9)/AN9-1),"") -> 0 | AP9: =IFERROR((H9*AF9/100)*(1+AO9),"") | AR9: =IFERROR(VLOOKUP(B9,OBJECTIFS!$C$76:$E$137,2,FALSE),0) -> 0 | AS9: =IFERROR(VLOOKUP(B9,OBJECTIFS!$H$76:$J$137,2,FALSE),0) -> 0 | AT9: =IFERROR(VLOOKUP(B9,OBJECTIFS!$C$142:$E$203,2,FALSE),0) -> 0 | AU9: =IFERROR(VLOOKUP(B9,OBJECTIFS!$H$142:$J$203,2,FALSE),0) -> 0 | AV9: =IFERROR(VLOOKUP(B9,OBJECTIFS!$F$208:$H$269,3,FALSE),0) -> 0 | AW9: =IF($B$5="interne",IF($AR$6="prime de langue",IF(AH9>=191,SUM(AS9:AV9,AR9/191*191),SUM(AS9:AV9,AR9/191*AH9)),IF($AS$6="prime de langue",IF(AH9>=191,SUM(AR9,AT9,AU9,AV9,AS9/191*191),SUM(AR9,AT9,AU9,AV9,AS9/191*AH9)),IF($AT$6="prime de langue",IF(AH9>=191,SUM(AR9,AS9,AU9,AV9,AT9/191*191),SUM(AR9,AS9,AU9,AV9,AT9/191*AH9)),IF($AU$6="prime de langue",IF(AH9>=191,SUM(AR9,AT9,AV9,AS9,AU9/191*191),SUM(AR9,AT9,AV9,AS9,AU9/191*AH9)),SUM(AR9:AV9))))),IF($AR$6="prime de langue",IF(AH9>=176,SUM(AS9:AV9,AR9/176*176),SUM(AS9:AV9,AR9/176*AH9)),IF($AS$6="prime de langue",IF(AH9>=176,SUM(AR9,AT9,AU9,AV9,AS9/176*176),SUM(AR9,AT9,AU9,AV9,AS9/176*AH9)),IF($AT$6="prime de langue",IF(AH9>=176,SUM(AR9,AS9,AU9,AV9,AT9/176*176),SUM(AR9,AS9,AU9,AV9,AT9/176*AH9)),IF($AU$6="prime de langue",IF(AH9>=176,SUM(AR9,AT9,AV9,AS9,AU9/176*176),SUM(AR9,AT9,AV9,AS9,AU9/176*AH9)),SUM(AR9:AV9)))))) -> 0 | AY9: =IFERROR(((H9*AF9/100)*(1+AO9)+AW9),"") | BA9: =IFERROR(IF(OR(AI9>=2,AJ9>=8,AND(AI9=1,AJ9>=4)),0,IF(OR(AND(AI9=1,AJ9<4),AND(AI9=0,AJ9>=4,AJ9<8)),0.5,1))*AF9*(AN9-AM9)/AN9,"") -> 0 | BB9: =IF(BC9="","","è") | BC9: =IF(BA9=0,"",IF(BA9>=MAX($BA$9:$BA$216),A9,""))
H10: =IF(OR(D10="",F10="",A10=""),"",IF(E10="oui",0,IF(D10=OBJECTIFS!$C$45,VLOOKUP(F10,OBJECTIFS!$C$9:$D$11,2,FALSE),IF(D10=OBJECTIFS!$C$46,VLOOKUP(F10,OBJECTIFS!$C$16:$D$18,2,FALSE),IF(D10=OBJECTIFS!$C$47,VLOOKUP(F10,OBJECTIFS!$C$23:$D$25,2,FALSE),IF(D10=OBJECTIFS!$C$48,VLOOKUP(F10,OBJECTIFS!$C$30:$D$32,2,FALSE),IF(D10=OBJECTIFS!$C$49,VLOOKUP(F10,OBJECTIFS!$C$37:$D$39,2,FALSE)))))))) | K10: =IF(OR($A10="",$D10="",J10=""),"",SUMIFS(OBJECTIFS!E$9:E$39,OBJECTIFS!$A$9:$A$39,$D10,OBJECTIFS!$C$9:$C$39,$F10)) | L10: =IF(OR(AND($D10=OBJECTIFS!$B$6,OBJECTIFS!E$8="dmt"),AND($D10=OBJECTIFS!$B$13,OBJECTIFS!$E$15="dmt"),AND($D10=OBJECTIFS!$B$20,OBJECTIFS!$E$22="dmt"),AND($D10=OBJECTIFS!$B$27,OBJECTIFS!$E$29="dmt"),AND($D10=OBJECTIFS!$B$34,OBJECTIFS!$E$36="dmt"),AND($D10=OBJECTIFS!$B$6,OBJECTIFS!$E$8="taux de chute"),AND($D10=OBJECTIFS!$B$13,OBJECTIFS!$E$15="taux de chute"),AND($D10=OBJECTIFS!$B$20,OBJECTIFS!$E$22="taux de chute"),AND($D10=OBJECTIFS!$B$27,OBJECTIFS!$E$29="taux de chute"),AND($D10=OBJECTIFS!$B$34,OBJECTIFS!$E$36="taux de chute")),IFERROR(K10/J10,""),IFERROR(J10/K10,"")) | M10: =IFERROR(IF(OR(J10="",K10="",L10=""),0,IF(L10<OBJECTIFS!$E$56,0,IF(L10<OBJECTIFS!$G$56,M$8*OBJECTIFS!$F$60,IF(L10<OBJECTIFS!$I$56,M$8*OBJECTIFS!$H$60,M$8)))),0) -> 0 | O10: =IF(OR($A10="",$D10="",N10=""),"",SUMIFS(OBJECTIFS!F$9:F$39,OBJECTIFS!$A$9:$A$39,$D10,OBJECTIFS!$C$9:$C$39,$F10)) | P10: =IF(OR(AND($D10=OBJECTIFS!$B$6,OBJECTIFS!$F$8="dmt"),AND($D10=OBJECTIFS!$B$13,OBJECTIFS!$F$15="dmt"),AND($D10=OBJECTIFS!$B$20,OBJECTIFS!$F$22="dmt"),AND($D10=OBJECTIFS!$B$27,OBJECTIFS!$F$29="dmt"),AND($D10=OBJECTIFS!$B$34,OBJECTIFS!$F$36="dmt"),AND($D10=OBJECTIFS!$B$6,OBJECTIFS!$F$8="taux de chute"),AND($D10=OBJECTIFS!$B$13,OBJECTIFS!$F$15="taux de chute"),AND($D10=OBJECTIFS!$B$20,OBJECTIFS!$F$22="taux de chute"),AND($D10=OBJECTIFS!$B$27,OBJECTIFS!$F$29="taux de chute"),AND($D10=OBJECTIFS!$B$34,OBJECTIFS!$F$36="taux de chute")),IFERROR(O10/N10,""),IFERROR(N10/O10,"")) | Q10: =IFERROR(IF(OR(N10="",O10="",P10=""),0,IF(P10<OBJECTIFS!$E$56,0,IF(P10<OBJECTIFS!$G$56,Q$8*OBJECTIFS!$F$60,IF(P10<OBJECTIFS!$I$56,Q$8*OBJECTIFS!$H$60,Q$8)))),0) -> 0 | S10: =IF(OR($A10="",$D10="",R10=""),"",SUMIFS(OBJECTIFS!G$9:G$39,OBJECTIFS!$A$9:$A$39,$D10,OBJECTIFS!$C$9:$C$39,$F10)) | T10: =IF(OR(AND($D10=OBJECTIFS!$B$6,OBJECTIFS!G$8="dmt"),AND($D10=OBJECTIFS!$B$13,OBJECTIFS!$G$15="dmt"),AND($D10=OBJECTIFS!$B$20,OBJECTIFS!$G$22="dmt"),AND($D10=OBJECTIFS!$B$27,OBJECTIFS!$G$29="dmt"),AND($D10=OBJECTIFS!$B$34,OBJECTIFS!$G$36="dmt"),AND($D10=OBJECTIFS!$B$6,OBJECTIFS!$G$8="taux de chute"),AND($D10=OBJECTIFS!$B$13,OBJECTIFS!$G$15="taux de chute"),AND($D10=OBJECTIFS!$B$20,OBJECTIFS!$G$22="taux de chute"),AND($D10=OBJECTIFS!$B$27,OBJECTIFS!$G$29="taux de chute"),AND($D10=OBJECTIFS!$B$34,OBJECTIFS!$G$36="taux de chute")),IFERROR(S10/R10,""),IFERROR(R10/S10,"")) | U10: =IFERROR(IF(OR(R10="",S10="",T10=""),0,IF(T10<OBJECTIFS!$E$56,0,IF(T10<OBJECTIFS!$G$56,U$8*OBJECTIFS!$F$60,IF(T10<OBJECTIFS!$I$56,U$8*OBJECTIFS!$H$60,U$8)))),0) -> 0 | W10: =IF(OR($A10="",$D10="",V10=""),"",SUMIFS(OBJECTIFS!H$9:H$39,OBJECTIFS!$A$9:$A$39,$D10,OBJECTIFS!$C$9:$C$39,$F10)) | X10: =IF(OR(AND($D10=OBJECTIFS!$B$6,OBJECTIFS!H$8="dmt"),AND($D10=OBJECTIFS!$B$13,OBJECTIFS!$H$15="dmt"),AND($D10=OBJECTIFS!$B$20,OBJECTIFS!$H$22="dmt"),AND($D10=OBJECTIFS!$B$27,OBJECTIFS!$H$29="dmt"),AND($D10=OBJECTIFS!$B$34,OBJECTIFS!$H$36="dmt"),AND($D10=OBJECTIFS!$B$6,OBJECTIFS!$H$8="taux de chute"),AND($D10=OBJECTIFS!$B$13,OBJECTIFS!$H$15="taux de chute"),AND($D10=OBJECTIFS!$B$20,OBJECTIFS!$H$22="taux de chute"),AND($D10=OBJECTIFS!$B$27,OBJECTIFS!$H$29="taux de chute"),AND($D10=OBJECTIFS!$B$34,OBJECTIFS!$H$36="taux de chute")),IFERROR(W10/V10,""),IFERROR(V10/W10,"")) | Y10: =IFERROR(IF(OR(V10="",W10="",X10=""),0,IF(X10<OBJECTIFS!$E$56,0,IF(X10<OBJECTIFS!$G$56,Y$8*OBJECTIFS!$F$60,IF(X10<OBJECTIFS!$I$56,Y$8*OBJECTIFS!$H$60,Y$8)))),0) -> 0 | AA10: =IF(OR($A10="",$D10="",Z10=""),"",SUMIFS(OBJECTIFS!I$9:I$39,OBJECTIFS!$A$9:$A$39,$D10,OBJECTIFS!$C$9:$C$39,$F10)) | AB10: =IF(OR(AND($D10=OBJECTIFS!$B$6,OBJECTIFS!I$8="dmt"),AND($D10=OBJECTIFS!$B$13,OBJECTIFS!$I$15="dmt"),AND($D10=OBJECTIFS!$B$20,OBJECTIFS!$I$22="dmt"),AND($D10=OBJECTIFS!$B$27,OBJECTIFS!$I$29="dmt"),AND($D10=OBJECTIFS!$B$34,OBJECTIFS!$I$36="dmt"),AND($D10=OBJECTIFS!$B$6,OBJECTIFS!$I$8="taux de chute"),AND($D10=OBJECTIFS!$B$13,OBJECTIFS!$I$15="taux de chute"),AND($D10=OBJECTIFS!$B$20,OBJECTIFS!$I$22="taux de chute"),AND($D10=OBJECTIFS!$B$27,OBJECTIFS!$I$29="taux de chute"),AND($D10=OBJECTIFS!$B$34,OBJECTIFS!$I$36="taux de chute")),IFERROR(AA10/Z10,""),IFERROR(Z10/AA10,"")) | AC10: =IFERROR(IF(OR(Z10="",AA10="",AB10=""),0,IF(AB10<OBJECTIFS!$E$56,0,IF(AB10<OBJECTIFS!$G$56,AC$8*OBJECTIFS!$F$60,IF(AB10<OBJECTIFS!$I$56,AC$8*OBJECTIFS!$H$60,AC$8)))),0) -> 0 | AF10: =IF(AD10>=1,0,SUMIF($J$7:$AC$8,"Nb de points",$J10:$AC10)) -> 0 | AM10: =SUM(AK10:AL10,AI10) -> 0 | AN10: 22 | AO10: =IFERROR(IF(IF(OR(AI10>=2,AJ10>=8,AND(AI10=1,AJ10>=4)),0,IF(OR(AND(AI10=1,AJ10<4),AND(AI10=0,AJ10>=4,AJ10<8)),50%,100%))*(AN10-AM10)/AN10=0,-100%,IF(OR(AI10>=2,AJ10>=8,AND(AI10=1,AJ10>=4)),0,IF(OR(AND(AI10=1,AJ10<4),AND(AI10=0,AJ10>=4,AJ10<8)),50%,100%))*(AN10-AM10)/AN10-1),"") -> 0 | AP10: =IFERROR((H10*AF10/100)*(1+AO10),"") | AR10: =IFERROR(VLOOKUP(B10,OBJECTIFS!$C$76:$E$137,2,FALSE),0) -> 0 | AS10: =IFERROR(VLOOKUP(B10,OBJECTIFS!$H$76:$J$137,2,FALSE),0) -> 0 | AT10: =IFERROR(VLOOKUP(B10,OBJECTIFS!$C$142:$E$203,2,FALSE),0) -> 0 | AU10: =IFERROR(VLOOKUP(B10,OBJECTIFS!$H$142:$J$203,2,FALSE),0) -> 0 | AV10: =IFERROR(VLOOKUP(B10,OBJECTIFS!$F$208:$H$269,3,FALSE),0) -> 0 | AW10: =IF($B$5="interne",IF($AR$6="prime de langue",IF(AH10>=191,SUM(AS10:AV10,AR10/191*191),SUM(AS10:AV10,AR10/191*AH10)),IF($AS$6="prime de langue",IF(AH10>=191,SUM(AR10,AT10,AU10,AV10,AS10/191*191),SUM(AR10,AT10,AU10,AV10,AS10/191*AH10)),IF($AT$6="prime de langue",IF(AH10>=191,SUM(AR10,AS10,AU10,AV10,AT10/191*191),SUM(AR10,AS10,AU10,AV10,AT10/191*AH10)),IF($AU$6="prime de langue",IF(AH10>=191,SUM(AR10,AT10,AV10,AS10,AU10/191*191),SUM(AR10,AT10,AV10,AS10,AU10/191*AH10)),SUM(AR10:AV10))))),IF($AR$6="prime de langue",IF(AH10>=176,SUM(AS10:AV10,AR10/176*176),SUM(AS10:AV10,AR10/176*AH10)),IF($AS$6="prime de langue",IF(AH10>=176,SUM(AR10,AT10,AU10,AV10,AS10/176*176),SUM(AR10,AT10,AU10,AV10,AS10/176*AH10)),IF($AT$6="prime de langue",IF(AH10>=176,SUM(AR10,AS10,AU10,AV10,AT10/176*176),SUM(AR10,AS10,AU10,AV10,AT10/176*AH10)),IF($AU$6="prime de langue",IF(AH10>=176,SUM(AR10,AT10,AV10,AS10,AU10/176*176),SUM(AR10,AT10,AV10,AS10,AU10/176*AH10)),SUM(AR10:AV10)))))) -> 0 | AY10: =IFERROR(((H10*AF10/100)*(1+AO10)+AW10),"") | BA10: =IFERROR(IF(OR(AI10>=2,AJ10>=8,AND(AI10=1,AJ10>=4)),0,IF(OR(AND(AI10=1,AJ10<4),AND(AI10=0,AJ10>=4,AJ10<8)),0.5,1))*AF10*(AN10-AM10)/AN10,"") -> 0 | BB10: =IF(BC10="","","è") | BC10: =IF(BA10=0,"",IF(BA10>=MAX($BA$9:$BA$216),A10,""))
H11: =IF(OR(D11="",F11="",A11=""),"",IF(E11="oui",0,IF(D11=OBJECTIFS!$C$45,VLOOKUP(F11,OBJECTIFS!$C$9:$D$11,2,FALSE),IF(D11=OBJECTIFS!$C$46,VLOOKUP(F11,OBJECTIFS!$C$16:$D$18,2,FALSE),IF(D11=OBJECTIFS!$C$47,VLOOKUP(F11,OBJECTIFS!$C$23:$D$25,2,FALSE),IF(D11=OBJECTIFS!$C$48,VLOOKUP(F11,OBJECTIFS!$C$30:$D$32,2,FALSE),IF(D11=OBJECTIFS!$C$49,VLOOKUP(F11,OBJECTIFS!$C$37:$D$39,2,FALSE)))))))) | K11: =IF(OR($A11="",$D11="",J11=""),"",SUMIFS(OBJECTIFS!E$9:E$39,OBJECTIFS!$A$9:$A$39,$D11,OBJECTIFS!$C$9:$C$39,$F11)) | L11: =IF(OR(AND($D11=OBJECTIFS!$B$6,OBJECTIFS!E$8="dmt"),AND($D11=OBJECTIFS!$B$13,OBJECTIFS!$E$15="dmt"),AND($D11=OBJECTIFS!$B$20,OBJECTIFS!$E$22="dmt"),AND($D11=OBJECTIFS!$B$27,OBJECTIFS!$E$29="dmt"),AND($D11=OBJECTIFS!$B$34,OBJECTIFS!$E$36="dmt"),AND($D11=OBJECTIFS!$B$6,OBJECTIFS!$E$8="taux de chute"),AND($D11=OBJECTIFS!$B$13,OBJECTIFS!$E$15="taux de chute"),AND($D11=OBJECTIFS!$B$20,OBJECTIFS!$E$22="taux de chute"),AND($D11=OBJECTIFS!$B$27,OBJECTIFS!$E$29="taux de chute"),AND($D11=OBJECTIFS!$B$34,OBJECTIFS!$E$36="taux de chute")),IFERROR(K11/J11,""),IFERROR(J11/K11,"")) | M11: =IFERROR(IF(OR(J11="",K11="",L11=""),0,IF(L11<OBJECTIFS!$E$56,0,IF(L11<OBJECTIFS!$G$56,M$8*OBJECTIFS!$F$60,IF(L11<OBJECTIFS!$I$56,M$8*OBJECTIFS!$H$60,M$8)))),0) -> 0 | O11: =IF(OR($A11="",$D11="",N11=""),"",SUMIFS(OBJECTIFS!F$9:F$39,OBJECTIFS!$A$9:$A$39,$D11,OBJECTIFS!$C$9:$C$39,$F11)) | P11: =IF(OR(AND($D11=OBJECTIFS!$B$6,OBJECTIFS!$F$8="dmt"),AND($D11=OBJECTIFS!$B$13,OBJECTIFS!$F$15="dmt"),AND($D11=OBJECTIFS!$B$20,OBJECTIFS!$F$22="dmt"),AND($D11=OBJECTIFS!$B$27,OBJECTIFS!$F$29="dmt"),AND($D11=OBJECTIFS!$B$34,OBJECTIFS!$F$36="dmt"),AND($D11=OBJECTIFS!$B$6,OBJECTIFS!$F$8="taux de chute"),AND($D11=OBJECTIFS!$B$13,OBJECTIFS!$F$15="taux de chute"),AND($D11=OBJECTIFS!$B$20,OBJECTIFS!$F$22="taux de chute"),AND($D11=OBJECTIFS!$B$27,OBJECTIFS!$F$29="taux de chute"),AND($D11=OBJECTIFS!$B$34,OBJECTIFS!$F$36="taux de chute")),IFERROR(O11/N11,""),IFERROR(N11/O11,"")) | Q11: =IFERROR(IF(OR(N11="",O11="",P11=""),0,IF(P11<OBJECTIFS!$E$56,0,IF(P11<OBJECTIFS!$G$56,Q$8*OBJECTIFS!$F$60,IF(P11<OBJECTIFS!$I$56,Q$8*OBJECTIFS!$H$60,Q$8)))),0) -> 0 | S11: =IF(OR($A11="",$D11="",R11=""),"",SUMIFS(OBJECTIFS!G$9:G$39,OBJECTIFS!$A$9:$A$39,$D11,OBJECTIFS!$C$9:$C$39,$F11)) | T11: =IF(OR(AND($D11=OBJECTIFS!$B$6,OBJECTIFS!G$8="dmt"),AND($D11=OBJECTIFS!$B$13,OBJECTIFS!$G$15="dmt"),AND($D11=OBJECTIFS!$B$20,OBJECTIFS!$G$22="dmt"),AND($D11=OBJECTIFS!$B$27,OBJECTIFS!$G$29="dmt"),AND($D11=OBJECTIFS!$B$34,OBJECTIFS!$G$36="dmt"),AND($D11=OBJECTIFS!$B$6,OBJECTIFS!$G$8="taux de chute"),AND($D11=OBJECTIFS!$B$13,OBJECTIFS!$G$15="taux de chute"),AND($D11=OBJECTIFS!$B$20,OBJECTIFS!$G$22="taux de chute"),AND($D11=OBJECTIFS!$B$27,OBJECTIFS!$G$29="taux de chute"),AND($D11=OBJECTIFS!$B$34,OBJECTIFS!$G$36="taux de chute")),IFERROR(S11/R11,""),IFERROR(R11/S11,"")) | U11: =IFERROR(IF(OR(R11="",S11="",T11=""),0,IF(T11<OBJECTIFS!$E$56,0,IF(T11<OBJECTIFS!$G$56,U$8*OBJECTIFS!$F$60,IF(T11<OBJECTIFS!$I$56,U$8*OBJECTIFS!$H$60,U$8)))),0) -> 0 | W11: =IF(OR($A11="",$D11="",V11=""),"",SUMIFS(OBJECTIFS!H$9:H$39,OBJECTIFS!$A$9:$A$39,$D11,OBJECTIFS!$C$9:$C$39,$F11)) | X11: =IF(OR(AND($D11=OBJECTIFS!$B$6,OBJECTIFS!H$8="dmt"),AND($D11=OBJECTIFS!$B$13,OBJECTIFS!$H$15="dmt"),AND($D11=OBJECTIFS!$B$20,OBJECTIFS!$H$22="dmt"),AND($D11=OBJECTIFS!$B$27,OBJECTIFS!$H$29="dmt"),AND($D11=OBJECTIFS!$B$34,OBJECTIFS!$H$36="dmt"),AND($D11=OBJECTIFS!$B$6,OBJECTIFS!$H$8="taux de chute"),AND($D11=OBJECTIFS!$B$13,OBJECTIFS!$H$15="taux de chute"),AND($D11=OBJECTIFS!$B$20,OBJECTIFS!$H$22="taux de chute"),AND($D11=OBJECTIFS!$B$27,OBJECTIFS!$H$29="taux de chute"),AND($D11=OBJECTIFS!$B$34,OBJECTIFS!$H$36="taux de chute")),IFERROR(W11/V11,""),IFERROR(V11/W11,"")) | Y11: =IFERROR(IF(OR(V11="",W11="",X11=""),0,IF(X11<OBJECTIFS!$E$56,0,IF(X11<OBJECTIFS!$G$56,Y$8*OBJECTIFS!$F$60,IF(X11<OBJECTIFS!$I$56,Y$8*OBJECTIFS!$H$60,Y$8)))),0) -> 0 | AA11: =IF(OR($A11="",$D11="",Z11=""),"",SUMIFS(OBJECTIFS!I$9:I$39,OBJECTIFS!$A$9:$A$39,$D11,OBJECTIFS!$C$9:$C$39,$F11)) | AB11: =IF(OR(AND($D11=OBJECTIFS!$B$6,OBJECTIFS!I$8="dmt"),AND($D11=OBJECTIFS!$B$13,OBJECTIFS!$I$15="dmt"),AND($D11=OBJECTIFS!$B$20,OBJECTIFS!$I$22="dmt"),AND($D11=OBJECTIFS!$B$27,OBJECTIFS!$I$29="dmt"),AND($D11=OBJECTIFS!$B$34,OBJECTIFS!$I$36="dmt"),AND($D11=OBJECTIFS!$B$6,OBJECTIFS!$I$8="taux de chute"),AND($D11=OBJECTIFS!$B$13,OBJECTIFS!$I$15="taux de chute"),AND($D11=OBJECTIFS!$B$20,OBJECTIFS!$I$22="taux de chute"),AND($D11=OBJECTIFS!$B$27,OBJECTIFS!$I$29="taux de chute"),AND($D11=OBJECTIFS!$B$34,OBJECTIFS!$I$36="taux de chute")),IFERROR(AA11/Z11,""),IFERROR(Z11/AA11,"")) | AC11: =IFERROR(IF(OR(Z11="",AA11="",AB11=""),0,IF(AB11<OBJECTIFS!$E$56,0,IF(AB11<OBJECTIFS!$G$56,AC$8*OBJECTIFS!$F$60,IF(AB11<OBJECTIFS!$I$56,AC$8*OBJECTIFS!$H$60,AC$8)))),0) -> 0 | AF11: =IF(AD11>=1,0,SUMIF($J$7:$AC$8,"Nb de points",$J11:$AC11)) -> 0 | AM11: =SUM(AK11:AL11,AI11) -> 0 | AN11: 22 | AO11: =IFERROR(IF(IF(OR(AI11>=2,AJ11>=8,AND(AI11=1,AJ11>=4)),0,IF(OR(AND(AI11=1,AJ11<4),AND(AI11=0,AJ11>=4,AJ11<8)),50%,100%))*(AN11-AM11)/AN11=0,-100%,IF(OR(AI11>=2,AJ11>=8,AND(AI11=1,AJ11>=4)),0,IF(OR(AND(AI11=1,AJ11<4),AND(AI11=0,AJ11>=4,AJ11<8)),50%,100%))*(AN11-AM11)/AN11-1),"") -> 0 | AP11: =IFERROR((H11*AF11/100)*(1+AO11),"") | AR11: =IFERROR(VLOOKUP(B11,OBJECTIFS!$C$76:$E$137,2,FALSE),0) -> 0 | AS11: =IFERROR(VLOOKUP(B11,OBJECTIFS!$H$76:$J$137,2,FALSE),0) -> 0 | AT11: =IFERROR(VLOOKUP(B11,OBJECTIFS!$C$142:$E$203,2,FALSE),0) -> 0 | AU11: =IFERROR(VLOOKUP(B11,OBJECTIFS!$H$142:$J$203,2,FALSE),0) -> 0 | AV11: =IFERROR(VLOOKUP(B11,OBJECTIFS!$F$208:$H$269,3,FALSE),0) -> 0 | AW11: =IF($B$5="interne",IF($AR$6="prime de langue",IF(AH11>=191,SUM(AS11:AV11,AR11/191*191),SUM(AS11:AV11,AR11/191*AH11)),IF($AS$6="prime de langue",IF(AH11>=191,SUM(AR11,AT11,AU11,AV11,AS11/191*191),SUM(AR11,AT11,AU11,AV11,AS11/191*AH11)),IF($AT$6="prime de langue",IF(AH11>=191,SUM(AR11,AS11,AU11,AV11,AT11/191*191),SUM(AR11,AS11,AU11,AV11,AT11/191*AH11)),IF($AU$6="prime de langue",IF(AH11>=191,SUM(AR11,AT11,AV11,AS11,AU11/191*191),SUM(AR11,AT11,AV11,AS11,AU11/191*AH11)),SUM(AR11:AV11))))),IF($AR$6="prime de langue",IF(AH11>=176,SUM(AS11:AV11,AR11/176*176),SUM(AS11:AV11,AR11/176*AH11)),IF($AS$6="prime de langue",IF(AH11>=176,SUM(AR11,AT11,AU11,AV11,AS11/176*176),SUM(AR11,AT11,AU11,AV11,AS11/176*AH11)),IF($AT$6="prime de langue",IF(AH11>=176,SUM(AR11,AS11,AU11,AV11,AT11/176*176),SUM(AR11,AS11,AU11,AV11,AT11/176*AH11)),IF($AU$6="prime de langue",IF(AH11>=176,SUM(AR11,AT11,AV11,AS11,AU11/176*176),SUM(AR11,AT11,AV11,AS11,AU11/176*AH11)),SUM(AR11:AV11)))))) -> 0 | AY11: =IFERROR(((H11*AF11/100)*(1+AO11)+AW11),"") | BA11: =IFERROR(IF(OR(AI11>=2,AJ11>=8,AND(AI11=1,AJ11>=4)),0,IF(OR(AND(AI11=1,AJ11<4),AND(AI11=0,AJ11>=4,AJ11<8)),0.5,1))*AF11*(AN11-AM11)/AN11,"") -> 0 | BB11: =IF(BC11="","","è") | BC11: =IF(BA11=0,"",IF(BA11>=MAX($BA$9:$BA$216),A11,""))
H12: =IF(OR(D12="",F12="",A12=""),"",IF(E12="oui",0,IF(D12=OBJECTIFS!$C$45,VLOOKUP(F12,OBJECTIFS!$C$9:$D$11,2,FALSE),IF(D12=OBJECTIFS!$C$46,VLOOKUP(F12,OBJECTIFS!$C$16:$D$18,2,FALSE),IF(D12=OBJECTIFS!$C$47,VLOOKUP(F12,OBJECTIFS!$C$23:$D$25,2,FALSE),IF(D12=OBJECTIFS!$C$48,VLOOKUP(F12,OBJECTIFS!$C$30:$D$32,2,FALSE),IF(D12=OBJECTIFS!$C$49,VLOOKUP(F12,OBJECTIFS!$C$37:$D$39,2,FALSE)))))))) | K12: =IF(OR($A12="",$D12="",J12=""),"",SUMIFS(OBJECTIFS!E$9:E$39,OBJECTIFS!$A$9:$A$39,$D12,OBJECTIFS!$C$9:$C$39,$F12)) | L12: =IF(OR(AND($D12=OBJECTIFS!$B$6,OBJECTIFS!E$8="dmt"),AND($D12=OBJECTIFS!$B$13,OBJECTIFS!$E$15="dmt"),AND($D12=OBJECTIFS!$B$20,OBJECTIFS!$E$22="dmt"),AND($D12=OBJECTIFS!$B$27,OBJECTIFS!$E$29="dmt"),AND($D12=OBJECTIFS!$B$34,OBJECTIFS!$E$36="dmt"),AND($D12=OBJECTIFS!$B$6,OBJECTIFS!$E$8="taux de chute"),AND($D12=OBJECTIFS!$B$13,OBJECTIFS!$E$15="taux de chute"),AND($D12=OBJECTIFS!$B$20,OBJECTIFS!$E$22="taux de chute"),AND($D12=OBJECTIFS!$B$27,OBJECTIFS!$E$29="taux de chute"),AND($D12=OBJECTIFS!$B$34,OBJECTIFS!$E$36="taux de chute")),IFERROR(K12/J12,""),IFERROR(J12/K12,"")) | M12: =IFERROR(IF(OR(J12="",K12="",L12=""),0,IF(L12<OBJECTIFS!$E$56,0,IF(L12<OBJECTIFS!$G$56,M$8*OBJECTIFS!$F$60,IF(L12<OBJECTIFS!$I$56,M$8*OBJECTIFS!$H$60,M$8)))),0) -> 0 | O12: =IF(OR($A12="",$D12="",N12=""),"",SUMIFS(OBJECTIFS!F$9:F$39,OBJECTIFS!$A$9:$A$39,$D12,OBJECTIFS!$C$9:$C$39,$F12)) | P12: =IF(OR(AND($D12=OBJECTIFS!$B$6,OBJECTIFS!$F$8="dmt"),AND($D12=OBJECTIFS!$B$13,OBJECTIFS!$F$15="dmt"),AND($D12=OBJECTIFS!$B$20,OBJECTIFS!$F$22="dmt"),AND($D12=OBJECTIFS!$B$27,OBJECTIFS!$F$29="dmt"),AND($D12=OBJECTIFS!$B$34,OBJECTIFS!$F$36="dmt"),AND($D12=OBJECTIFS!$B$6,OBJECTIFS!$F$8="taux de chute"),AND($D12=OBJECTIFS!$B$13,OBJECTIFS!$F$15="taux de chute"),AND($D12=OBJECTIFS!$B$20,OBJECTIFS!$F$22="taux de chute"),AND($D12=OBJECTIFS!$B$27,OBJECTIFS!$F$29="taux de chute"),AND($D12=OBJECTIFS!$B$34,OBJECTIFS!$F$36="taux de chute")),IFERROR(O12/N12,""),IFERROR(N12/O12,"")) | Q12: =IFERROR(IF(OR(N12="",O12="",P12=""),0,IF(P12<OBJECTIFS!$E$56,0,IF(P12<OBJECTIFS!$G$56,Q$8*OBJECTIFS!$F$60,IF(P12<OBJECTIFS!$I$56,Q$8*OBJECTIFS!$H$60,Q$8)))),0) -> 0 | S12: =IF(OR($A12="",$D12="",R12=""),"",SUMIFS(OBJECTIFS!G$9:G$39,OBJECTIFS!$A$9:$A$39,$D12,OBJECTIFS!$C$9:$C$39,$F12)) | T12: =IF(OR(AND($D12=OBJECTIFS!$B$6,OBJECTIFS!G$8="dmt"),AND($D12=OBJECTIFS!$B$13,OBJECTIFS!$G$15="dmt"),AND($D12=OBJECTIFS!$B$20,OBJECTIFS!$G$22="dmt"),AND($D12=OBJECTIFS!$B$27,OBJECTIFS!$G$29="dmt"),AND($D12=OBJECTIFS!$B$34,OBJECTIFS!$G$36="dmt"),AND($D12=OBJECTIFS!$B$6,OBJECTIFS!$G$8="taux de chute"),AND($D12=OBJECTIFS!$B$13,OBJECTIFS!$G$15="taux de chute"),AND($D12=OBJECTIFS!$B$20,OBJECTIFS!$G$22="taux de chute"),AND($D12=OBJECTIFS!$B$27,OBJECTIFS!$G$29="taux de chute"),AND($D12=OBJECTIFS!$B$34,OBJECTIFS!$G$36="taux de chute")),IFERROR(S12/R12,""),IFERROR(R12/S12,"")) | U12: =IFERROR(IF(OR(R12="",S12="",T12=""),0,IF(T12<OBJECTIFS!$E$56,0,IF(T12<OBJECTIFS!$G$56,U$8*OBJECTIFS!$F$60,IF(T12<OBJECTIFS!$I$56,U$8*OBJECTIFS!$H$60,U$8)))),0) -> 0 | W12: =IF(OR($A12="",$D12="",V12=""),"",SUMIFS(OBJECTIFS!H$9:H$39,OBJECTIFS!$A$9:$A$39,$D12,OBJECTIFS!$C$9:$C$39,$F12)) | X12: =IF(OR(AND($D12=OBJECTIFS!$B$6,OBJECTIFS!H$8="dmt"),AND($D12=OBJECTIFS!$B$13,OBJECTIFS!$H$15="dmt"),AND($D12=OBJECTIFS!$B$20,OBJECTIFS!$H$22="dmt"),AND($D12=OBJECTIFS!$B$27,OBJECTIFS!$H$29="dmt"),AND($D12=OBJECTIFS!$B$34,OBJECTIFS!$H$36="dmt"),AND($D12=OBJECTIFS!$B$6,OBJECTIFS!$H$8="taux de chute"),AND($D12=OBJECTIFS!$B$13,OBJECTIFS!$H$15="taux de chute"),AND($D12=OBJECTIFS!$B$20,OBJECTIFS!$H$22="taux de chute"),AND($D12=OBJECTIFS!$B$27,OBJECTIFS!$H$29="taux de chute"),AND($D12=OBJECTIFS!$B$34,OBJECTIFS!$H$36="taux de chute")),IFERROR(W12/V12,""),IFERROR(V12/W12,"")) | Y12: =IFERROR(IF(OR(V12="",W12="",X12=""),0,IF(X12<OBJECTIFS!$E$56,0,IF(X12<OBJECTIFS!$G$56,Y$8*OBJECTIFS!$F$60,IF(X12<OBJECTIFS!$I$56,Y$8*OBJECTIFS!$H$60,Y$8)))),0) -> 0 | AA12: =IF(OR($A12="",$D12="",Z12=""),"",SUMIFS(OBJECTIFS!I$9:I$39,OBJECTIFS!$A$9:$A$39,$D12,OBJECTIFS!$C$9:$C$39,$F12)) | AB12: =IF(OR(AND($D12=OBJECTIFS!$B$6,OBJECTIFS!I$8="dmt"),AND($D12=OBJECTIFS!$B$13,OBJECTIFS!$I$15="dmt"),AND($D12=OBJECTIFS!$B$20,OBJECTIFS!$I$22="dmt"),AND($D12=OBJECTIFS!$B$27,OBJECTIFS!$I$29="dmt"),AND($D12=OBJECTIFS!$B$34,OBJECTIFS!$I$36="dmt"),AND($D12=OBJECTIFS!$B$6,OBJECTIFS!$I$8="taux de chute"),AND($D12=OBJECTIFS!$B$13,OBJECTIFS!$I$15="taux de chute"),AND($D12=OBJECTIFS!$B$20,OBJECTIFS!$I$22="taux de chute"),AND($D12=OBJECTIFS!$B$27,OBJECTIFS!$I$29="taux de chute"),AND($D12=OBJECTIFS!$B$34,OBJECTIFS!$I$36="taux de chute")),IFERROR(AA12/Z12,""),IFERROR(Z12/AA12,"")) | AC12: =IFERROR(IF(OR(Z12="",AA12="",AB12=""),0,IF(AB12<OBJECTIFS!$E$56,0,IF(AB12<OBJECTIFS!$G$56,AC$8*OBJECTIFS!$F$60,IF(AB12<OBJECTIFS!$I$56,AC$8*OBJECTIFS!$H$60,AC$8)))),0) -> 0 | AF12: =IF(AD12>=1,0,SUMIF($J$7:$AC$8,"Nb de points",$J12:$AC12)) -> 0 | AM12: =SUM(AK12:AL12,AI12) -> 0 | AN12: 22 | AO12: =IFERROR(IF(IF(OR(AI12>=2,AJ12>=8,AND(AI12=1,AJ12>=4)),0,IF(OR(AND(AI12=1,AJ12<4),AND(AI12=0,AJ12>=4,AJ12<8)),50%,100%))*(AN12-AM12)/AN12=0,-100%,IF(OR(AI12>=2,AJ12>=8,AND(AI12=1,AJ12>=4)),0,IF(OR(AND(AI12=1,AJ12<4),AND(AI12=0,AJ12>=4,AJ12<8)),50%,100%))*(AN12-AM12)/AN12-1),"") -> 0 | AP12: =IFERROR((H12*AF12/100)*(1+AO12),"") | AR12: =IFERROR(VLOOKUP(B12,OBJECTIFS!$C$76:$E$137,2,FALSE),0) -> 0 | AS12: =IFERROR(VLOOKUP(B12,OBJECTIFS!$H$76:$J$137,2,FALSE),0) -> 0 | AT12: =IFERROR(VLOOKUP(B12,OBJECTIFS!$C$142:$E$203,2,FALSE),0) -> 0 | AU12: =IFERROR(VLOOKUP(B12,OBJECTIFS!$H$142:$J$203,2,FALSE),0) -> 0 | AV12: =IFERROR(VLOOKUP(B12,OBJECTIFS!$F$208:$H$269,3,FALSE),0) -> 0 | AW12: =IF($B$5="interne",IF($AR$6="prime de langue",IF(AH12>=191,SUM(AS12:AV12,AR12/191*191),SUM(AS12:AV12,AR12/191*AH12)),IF($AS$6="prime de langue",IF(AH12>=191,SUM(AR12,AT12,AU12,AV12,AS12/191*191),SUM(AR12,AT12,AU12,AV12,AS12/191*AH12)),IF($AT$6="prime de langue",IF(AH12>=191,SUM(AR12,AS12,AU12,AV12,AT12/191*191),SUM(AR12,AS12,AU12,AV12,AT12/191*AH12)),IF($AU$6="prime de langue",IF(AH12>=191,SUM(AR12,AT12,AV12,AS12,AU12/191*191),SUM(AR12,AT12,AV12,AS12,AU12/191*AH12)),SUM(AR12:AV12))))),IF($AR$6="prime de langue",IF(AH12>=176,SUM(AS12:AV12,AR12/176*176),SUM(AS12:AV12,AR12/176*AH12)),IF($AS$6="prime de langue",IF(AH12>=176,SUM(AR12,AT12,AU12,AV12,AS12/176*176),SUM(AR12,AT12,AU12,AV12,AS12/176*AH12)),IF($AT$6="prime de langue",IF(AH12>=176,SUM(AR12,AS12,AU12,AV12,AT12/176*176),SUM(AR12,AS12,AU12,AV12,AT12/176*AH12)),IF($AU$6="prime de langue",IF(AH12>=176,SUM(AR12,AT12,AV12,AS12,AU12/176*176),SUM(AR12,AT12,AV12,AS12,AU12/176*AH12)),SUM(AR12:AV12)))))) -> 0 | AY12: =IFERROR(((H12*AF12/100)*(1+AO12)+AW12),"") | BA12: =IFERROR(IF(OR(AI12>=2,AJ12>=8,AND(AI12=1,AJ12>=4)),0,IF(OR(AND(AI12=1,AJ12<4),AND(AI12=0,AJ12>=4,AJ12<8)),0.5,1))*AF12*(AN12-AM12)/AN12,"") -> 0 | BB12: =IF(BC12="","","è") | BC12: =IF(BA12=0,"",IF(BA12>=MAX($BA$9:$BA$216),A12,""))
H13: =IF(OR(D13="",F13="",A13=""),"",IF(E13="oui",0,IF(D13=OBJECTIFS!$C$45,VLOOKUP(F13,OBJECTIFS!$C$9:$D$11,2,FALSE),IF(D13=OBJECTIFS!$C$46,VLOOKUP(F13,OBJECTIFS!$C$16:$D$18,2,FALSE),IF(D13=OBJECTIFS!$C$47,VLOOKUP(F13,OBJECTIFS!$C$23:$D$25,2,FALSE),IF(D13=OBJECTIFS!$C$48,VLOOKUP(F13,OBJECTIFS!$C$30:$D$32,2,FALSE),IF(D13=OBJECTIFS!$C$49,VLOOKUP(F13,OBJECTIFS!$C$37:$D$39,2,FALSE)))))))) | K13: =IF(OR($A13="",$D13="",J13=""),"",SUMIFS(OBJECTIFS!E$9:E$39,OBJECTIFS!$A$9:$A$39,$D13,OBJECTIFS!$C$9:$C$39,$F13)) | L13: =IF(OR(AND($D13=OBJECTIFS!$B$6,OBJECTIFS!E$8="dmt"),AND($D13=OBJECTIFS!$B$13,OBJECTIFS!$E$15="dmt"),AND($D13=OBJECTIFS!$B$20,OBJECTIFS!$E$22="dmt"),AND($D13=OBJECTIFS!$B$27,OBJECTIFS!$E$29="dmt"),AND($D13=OBJECTIFS!$B$34,OBJECTIFS!$E$36="dmt"),AND($D13=OBJECTIFS!$B$6,OBJECTIFS!$E$8="taux de chute"),AND($D13=OBJECTIFS!$B$13,OBJECTIFS!$E$15="taux de chute"),AND($D13=OBJECTIFS!$B$20,OBJECTIFS!$E$22="taux de chute"),AND($D13=OBJECTIFS!$B$27,OBJECTIFS!$E$29="taux de chute"),AND($D13=OBJECTIFS!$B$34,OBJECTIFS!$E$36="taux de chute")),IFERROR(K13/J13,""),IFERROR(J13/K13,"")) | M13: =IFERROR(IF(OR(J13="",K13="",L13=""),0,IF(L13<OBJECTIFS!$E$56,0,IF(L13<OBJECTIFS!$G$56,M$8*OBJECTIFS!$F$60,IF(L13<OBJECTIFS!$I$56,M$8*OBJECTIFS!$H$60,M$8)))),0) -> 0 | O13: =IF(OR($A13="",$D13="",N13=""),"",SUMIFS(OBJECTIFS!F$9:F$39,OBJECTIFS!$A$9:$A$39,$D13,OBJECTIFS!$C$9:$C$39,$F13)) | P13: =IF(OR(AND($D13=OBJECTIFS!$B$6,OBJECTIFS!$F$8="dmt"),AND($D13=OBJECTIFS!$B$13,OBJECTIFS!$F$15="dmt"),AND($D13=OBJECTIFS!$B$20,OBJECTIFS!$F$22="dmt"),AND($D13=OBJECTIFS!$B$27,OBJECTIFS!$F$29="dmt"),AND($D13=OBJECTIFS!$B$34,OBJECTIFS!$F$36="dmt"),AND($D13=OBJECTIFS!$B$6,OBJECTIFS!$F$8="taux de chute"),AND($D13=OBJECTIFS!$B$13,OBJECTIFS!$F$15="taux de chute"),AND($D13=OBJECTIFS!$B$20,OBJECTIFS!$F$22="taux de chute"),AND($D13=OBJECTIFS!$B$27,OBJECTIFS!$F$29="taux de chute"),AND($D13=OBJECTIFS!$B$34,OBJECTIFS!$F$36="taux de chute")),IFERROR(O13/N13,""),IFERROR(N13/O13,"")) | Q13: =IFERROR(IF(OR(N13="",O13="",P13=""),0,IF(P13<OBJECTIFS!$E$56,0,IF(P13<OBJECTIFS!$G$56,Q$8*OBJECTIFS!$F$60,IF(P13<OBJECTIFS!$I$56,Q$8*OBJECTIFS!$H$60,Q$8)))),0) -> 0 | S13: =IF(OR($A13="",$D13="",R13=""),"",SUMIFS(OBJECTIFS!G$9:G$39,OBJECTIFS!$A$9:$A$39,$D13,OBJECTIFS!$C$9:$C$39,$F13)) | T13: =IF(OR(AND($D13=OBJECTIFS!$B$6,OBJECTIFS!G$8="dmt"),AND($D13=OBJECTIFS!$B$13,OBJECTIFS!$G$15="dmt"),AND($D13=OBJECTIFS!$B$20,OBJECTIFS!$G$22="dmt"),AND($D13=OBJECTIFS!$B$27,OBJECTIFS!$G$29="dmt"),AND($D13=OBJECTIFS!$B$34,OBJECTIFS!$G$36="dmt"),AND($D13=OBJECTIFS!$B$6,OBJECTIFS!$G$8="taux de chute"),AND($D13=OBJECTIFS!$B$13,OBJECTIFS!$G$15="taux de chute"),AND($D13=OBJECTIFS!$B$20,OBJECTIFS!$G$22="taux de chute"),AND($D13=OBJECTIFS!$B$27,OBJECTIFS!$G$29="taux de chute"),AND($D13=OBJECTIFS!$B$34,OBJECTIFS!$G$36="taux de chute")),IFERROR(S13/R13,""),IFERROR(R13/S13,"")) | U13: =IFERROR(IF(OR(R13="",S13="",T13=""),0,IF(T13<OBJECTIFS!$E$56,0,IF(T13<OBJECTIFS!$G$56,U$8*OBJECTIFS!$F$60,IF(T13<OBJECTIFS!$I$56,U$8*OBJECTIFS!$H$60,U$8)))),0) -> 0 | W13: =IF(OR($A13="",$D13="",V13=""),"",SUMIFS(OBJECTIFS!H$9:H$39,OBJECTIFS!$A$9:$A$39,$D13,OBJECTIFS!$C$9:$C$39,$F13)) | X13: =IF(OR(AND($D13=OBJECTIFS!$B$6,OBJECTIFS!H$8="dmt"),AND($D13=OBJECTIFS!$B$13,OBJECTIFS!$H$15="dmt"),AND($D13=OBJECTIFS!$B$20,OBJECTIFS!$H$22="dmt"),AND($D13=OBJECTIFS!$B$27,OBJECTIFS!$H$29="dmt"),AND($D13=OBJECTIFS!$B$34,OBJECTIFS!$H$36="dmt"),AND($D13=OBJECTIFS!$B$6,OBJECTIFS!$H$8="taux de chute"),AND($D13=OBJECTIFS!$B$13,OBJECTIFS!$H$15="taux de chute"),AND($D13=OBJECTIFS!$B$20,OBJECTIFS!$H$22="taux de chute"),AND($D13=OBJECTIFS!$B$27,OBJECTIFS!$H$29="taux de chute"),AND($D13=OBJECTIFS!$B$34,OBJECTIFS!$H$36="taux de chute")),IFERROR(W13/V13,""),IFERROR(V13/W13,"")) | Y13: =IFERROR(IF(OR(V13="",W13="",X13=""),0,IF(X13<OBJECTIFS!$E$56,0,IF(X13<OBJECTIFS!$G$56,Y$8*OBJECTIFS!$F$60,IF(X13<OBJECTIFS!$I$56,Y$8*OBJECTIFS!$H$60,Y$8)))),0) -> 0 | AA13: =IF(OR($A13="",$D13="",Z13=""),"",SUMIFS(OBJECTIFS!I$9:I$39,OBJECTIFS!$A$9:$A$39,$D13,OBJECTIFS!$C$9:$C$39,$F13)) | AB13: =IF(OR(AND($D13=OBJECTIFS!$B$6,OBJECTIFS!I$8="dmt"),AND($D13=OBJECTIFS!$B$13,OBJECTIFS!$I$15="dmt"),AND($D13=OBJECTIFS!$B$20,OBJECTIFS!$I$22="dmt"),AND($D13=OBJECTIFS!$B$27,OBJECTIFS!$I$29="dmt"),AND($D13=OBJECTIFS!$B$34,OBJECTIFS!$I$36="dmt"),AND($D13=OBJECTIFS!$B$6,OBJECTIFS!$I$8="taux de chute"),AND($D13=OBJECTIFS!$B$13,OBJECTIFS!$I$15="taux de chute"),AND($D13=OBJECTIFS!$B$20,OBJECTIFS!$I$22="taux de chute"),AND($D13=OBJECTIFS!$B$27,OBJECTIFS!$I$29="taux de chute"),AND($D13=OBJECTIFS!$B$34,OBJECTIFS!$I$36="taux de chute")),IFERROR(AA13/Z13,""),IFERROR(Z13/AA13,"")) | AC13: =IFERROR(IF(OR(Z13="",AA13="",AB13=""),0,IF(AB13<OBJECTIFS!$E$56,0,IF(AB13<OBJECTIFS!$G$56,AC$8*OBJECTIFS!$F$60,IF(AB13<OBJECTIFS!$I$56,AC$8*OBJECTIFS!$H$60,AC$8)))),0) -> 0 | AF13: =IF(AD13>=1,0,SUMIF($J$7:$AC$8,"Nb de points",$J13:$AC13)) -> 0 | AM13: =SUM(AK13:AL13,AI13) -> 0 | AN13: 22 | AO13: =IFERROR(IF(IF(OR(AI13>=2,AJ13>=8,AND(AI13=1,AJ13>=4)),0,IF(OR(AND(AI13=1,AJ13<4),AND(AI13=0,AJ13>=4,AJ13<8)),50%,100%))*(AN13-AM13)/AN13=0,-100%,IF(OR(AI13>=2,AJ13>=8,AND(AI13=1,AJ13>=4)),0,IF(OR(AND(AI13=1,AJ13<4),AND(AI13=0,AJ13>=4,AJ13<8)),50%,100%))*(AN13-AM13)/AN13-1),"") -> 0 | AP13: =IFERROR((H13*AF13/100)*(1+AO13),"") | AR13: =IFERROR(VLOOKUP(B13,OBJECTIFS!$C$76:$E$137,2,FALSE),0) -> 0 | AS13: =IFERROR(VLOOKUP(B13,OBJECTIFS!$H$76:$J$137,2,FALSE),0) -> 0 | AT13: =IFERROR(VLOOKUP(B13,OBJECTIFS!$C$142:$E$203,2,FALSE),0) -> 0 | AU13: =IFERROR(VLOOKUP(B13,OBJECTIFS!$H$142:$J$203,2,FALSE),0) -> 0 | AV13: =IFERROR(VLOOKUP(B13,OBJECTIFS!$F$208:$H$269,3,FALSE),0) -> 0 | AW13: =IF($B$5="interne",IF($AR$6="prime de langue",IF(AH13>=191,SUM(AS13:AV13,AR13/191*191),SUM(AS13:AV13,AR13/191*AH13)),IF($AS$6="prime de langue",IF(AH13>=191,SUM(AR13,AT13,AU13,AV13,AS13/191*191),SUM(AR13,AT13,AU13,AV13,AS13/191*AH13)),IF($AT$6="prime de langue",IF(AH13>=191,SUM(AR13,AS13,AU13,AV13,AT13/191*191),SUM(AR13,AS13,AU13,AV13,AT13/191*AH13)),IF($AU$6="prime de langue",IF(AH13>=191,SUM(AR13,AT13,AV13,AS13,AU13/191*191),SUM(AR13,AT13,AV13,AS13,AU13/191*AH13)),SUM(AR13:AV13))))),IF($AR$6="prime de langue",IF(AH13>=176,SUM(AS13:AV13,AR13/176*176),SUM(AS13:AV13,AR13/176*AH13)),IF($AS$6="prime de langue",IF(AH13>=176,SUM(AR13,AT13,AU13,AV13,AS13/176*176),SUM(AR13,AT13,AU13,AV13,AS13/176*AH13)),IF($AT$6="prime de langue",IF(AH13>=176,SUM(AR13,AS13,AU13,AV13,AT13/176*176),SUM(AR13,AS13,AU13,AV13,AT13/176*AH13)),IF($AU$6="prime de langue",IF(AH13>=176,SUM(AR13,AT13,AV13,AS13,AU13/176*176),SUM(AR13,AT13,AV13,AS13,AU13/176*AH13)),SUM(AR13:AV13)))))) -> 0 | AY13: =IFERROR(((H13*AF13/100)*(1+AO13)+AW13),"") | BA13: =IFERROR(IF(OR(AI13>=2,AJ13>=8,AND(AI13=1,AJ13>=4)),0,IF(OR(AND(AI13=1,AJ13<4),AND(AI13=0,AJ13>=4,AJ13<8)),0.5,1))*AF13*(AN13-AM13)/AN13,"") -> 0 | BB13: =IF(BC13="","","è") | BC13: =IF(BA13=0,"",IF(BA13>=MAX($BA$9:$BA$216),A13,""))
H14: =IF(OR(D14="",F14="",A14=""),"",IF(E14="oui",0,IF(D14=OBJECTIFS!$C$45,VLOOKUP(F14,OBJECTIFS!$C$9:$D$11,2,FALSE),IF(D14=OBJECTIFS!$C$46,VLOOKUP(F14,OBJECTIFS!$C$16:$D$18,2,FALSE),IF(D14=OBJECTIFS!$C$47,VLOOKUP(F14,OBJECTIFS!$C$23:$D$25,2,FALSE),IF(D14=OBJECTIFS!$C$48,VLOOKUP(F14,OBJECTIFS!$C$30:$D$32,2,FALSE),IF(D14=OBJECTIFS!$C$49,VLOOKUP(F14,OBJECTIFS!$C$37:$D$39,2,FALSE)))))))) | K14: =IF(OR($A14="",$D14="",J14=""),"",SUMIFS(OBJECTIFS!E$9:E$39,OBJECTIFS!$A$9:$A$39,$D14,OBJECTIFS!$C$9:$C$39,$F14)) | L14: =IF(OR(AND($D14=OBJECTIFS!$B$6,OBJECTIFS!E$8="dmt"),AND($D14=OBJECTIFS!$B$13,OBJECTIFS!$E$15="dmt"),AND($D14=OBJECTIFS!$B$20,OBJECTIFS!$E$22="dmt"),AND($D14=OBJECTIFS!$B$27,OBJECTIFS!$E$29="dmt"),AND($D14=OBJECTIFS!$B$34,OBJECTIFS!$E$36="dmt"),AND($D14=OBJECTIFS!$B$6,OBJECTIFS!$E$8="taux de chute"),AND($D14=OBJECTIFS!$B$13,OBJECTIFS!$E$15="taux de chute"),AND($D14=OBJECTIFS!$B$20,OBJECTIFS!$E$22="taux de chute"),AND($D14=OBJECTIFS!$B$27,OBJECTIFS!$E$29="taux de chute"),AND($D14=OBJECTIFS!$B$34,OBJECTIFS!$E$36="taux de chute")),IFERROR(K14/J14,""),IFERROR(J14/K14,"")) | M14: =IFERROR(IF(OR(J14="",K14="",L14=""),0,IF(L14<OBJECTIFS!$E$56,0,IF(L14<OBJECTIFS!$G$56,M$8*OBJECTIFS!$F$60,IF(L14<OBJECTIFS!$I$56,M$8*OBJECTIFS!$H$60,M$8)))),0) -> 0 | O14: =IF(OR($A14="",$D14="",N14=""),"",SUMIFS(OBJECTIFS!F$9:F$39,OBJECTIFS!$A$9:$A$39,$D14,OBJECTIFS!$C$9:$C$39,$F14)) | P14: =IF(OR(AND($D14=OBJECTIFS!$B$6,OBJECTIFS!$F$8="dmt"),AND($D14=OBJECTIFS!$B$13,OBJECTIFS!$F$15="dmt"),AND($D14=OBJECTIFS!$B$20,OBJECTIFS!$F$22="dmt"),AND($D14=OBJECTIFS!$B$27,OBJECTIFS!$F$29="dmt"),AND($D14=OBJECTIFS!$B$34,OBJECTIFS!$F$36="dmt"),AND($D14=OBJECTIFS!$B$6,OBJECTIFS!$F$8="taux de chute"),AND($D14=OBJECTIFS!$B$13,OBJECTIFS!$F$15="taux de chute"),AND($D14=OBJECTIFS!$B$20,OBJECTIFS!$F$22="taux de chute"),AND($D14=OBJECTIFS!$B$27,OBJECTIFS!$F$29="taux de chute"),AND($D14=OBJECTIFS!$B$34,OBJECTIFS!$F$36="taux de chute")),IFERROR(O14/N14,""),IFERROR(N14/O14,"")) | Q14: =IFERROR(IF(OR(N14="",O14="",P14=""),0,IF(P14<OBJECTIFS!$E$56,0,IF(P14<OBJECTIFS!$G$56,Q$8*OBJECTIFS!$F$60,IF(P14<OBJECTIFS!$I$56,Q$8*OBJECTIFS!$H$60,Q$8)))),0) -> 0 | S14: =IF(OR($A14="",$D14="",R14=""),"",SUMIFS(OBJECTIFS!G$9:G$39,OBJECTIFS!$A$9:$A$39,$D14,OBJECTIFS!$C$9:$C$39,$F14)) | T14: =IF(OR(AND($D14=OBJECTIFS!$B$6,OBJECTIFS!G$8="dmt"),AND($D14=OBJECTIFS!$B$13,OBJECTIFS!$G$15="dmt"),AND($D14=OBJECTIFS!$B$20,OBJECTIFS!$G$22="dmt"),AND($D14=OBJECTIFS!$B$27,OBJECTIFS!$G$29="dmt"),AND($D14=OBJECTIFS!$B$34,OBJECTIFS!$G$36="dmt"),AND($D14=OBJECTIFS!$B$6,OBJECTIFS!$G$8="taux de chute"),AND($D14=OBJECTIFS!$B$13,OBJECTIFS!$G$15="taux de chute"),AND($D14=OBJECTIFS!$B$20,OBJECTIFS!$G$22="taux de chute"),AND($D14=OBJECTIFS!$B$27,OBJECTIFS!$G$29="taux de chute"),AND($D14=OBJECTIFS!$B$34,OBJECTIFS!$G$36="taux de chute")),IFERROR(S14/R14,""),IFERROR(R14/S14,"")) | U14: =IFERROR(IF(OR(R14="",S14="",T14=""),0,IF(T14<OBJECTIFS!$E$56,0,IF(T14<OBJECTIFS!$G$56,U$8*OBJECTIFS!$F$60,IF(T14<OBJECTIFS!$I$56,U$8*OBJECTIFS!$H$60,U$8)))),0) -> 0 | W14: =IF(OR($A14="",$D14="",V14=""),"",SUMIFS(OBJECTIFS!H$9:H$39,OBJECTIFS!$A$9:$A$39,$D14,OBJECTIFS!$C$9:$C$39,$F14)) | X14: =IF(OR(AND($D14=OBJECTIFS!$B$6,OBJECTIFS!H$8="dmt"),AND($D14=OBJECTIFS!$B$13,OBJECTIFS!$H$15="dmt"),AND($D14=OBJECTIFS!$B$20,OBJECTIFS!$H$22="dmt"),AND($D14=OBJECTIFS!$B$27,OBJECTIFS!$H$29="dmt"),AND($D14=OBJECTIFS!$B$34,OBJECTIFS!$H$36="dmt"),AND($D14=OBJECTIFS!$B$6,OBJECTIFS!$H$8="taux de chute"),AND($D14=OBJECTIFS!$B$13,OBJECTIFS!$H$15="taux de chute"),AND($D14=OBJECTIFS!$B$20,OBJECTIFS!$H$22="taux de chute"),AND($D14=OBJECTIFS!$B$27,OBJECTIFS!$H$29="taux de chute"),AND($D14=OBJECTIFS!$B$34,OBJECTIFS!$H$36="taux de chute")),IFERROR(W14/V14,""),IFERROR(V14/W14,"")) | Y14: =IFERROR(IF(OR(V14="",W14="",X14=""),0,IF(X14<OBJECTIFS!$E$56,0,IF(X14<OBJECTIFS!$G$56,Y$8*OBJECTIFS!$F$60,IF(X14<OBJECTIFS!$I$56,Y$8*OBJECTIFS!$H$60,Y$8)))),0) -> 0 | AA14: =IF(OR($A14="",$D14="",Z14=""),"",SUMIFS(OBJECTIFS!I$9:I$39,OBJECTIFS!$A$9:$A$39,$D14,OBJECTIFS!$C$9:$C$39,$F14)) | AB14: =IF(OR(AND($D14=OBJECTIFS!$B$6,OBJECTIFS!I$8="dmt"),AND($D14=OBJECTIFS!$B$13,OBJECTIFS!$I$15="dmt"),AND($D14=OBJECTIFS!$B$20,OBJECTIFS!$I$22="dmt"),AND($D14=OBJECTIFS!$B$27,OBJECTIFS!$I$29="dmt"),AND($D14=OBJECTIFS!$B$34,OBJECTIFS!$I$36="dmt"),AND($D14=OBJECTIFS!$B$6,OBJECTIFS!$I$8="taux de chute"),AND($D14=OBJECTIFS!$B$13,OBJECTIFS!$I$15="taux de chute"),AND($D14=OBJECTIFS!$B$20,OBJECTIFS!$I$22="taux de chute"),AND($D14=OBJECTIFS!$B$27,OBJECTIFS!$I$29="taux de chute"),AND($D14=OBJECTIFS!$B$34,OBJECTIFS!$I$36="taux de chute")),IFERROR(AA14/Z14,""),IFERROR(Z14/AA14,"")) | AC14: =IFERROR(IF(OR(Z14="",AA14="",AB14=""),0,IF(AB14<OBJECTIFS!$E$56,0,IF(AB14<OBJECTIFS!$G$56,AC$8*OBJECTIFS!$F$60,IF(AB14<OBJECTIFS!$I$56,AC$8*OBJECTIFS!$H$60,AC$8)))),0) -> 0 | AF14: =IF(AD14>=1,0,SUMIF($J$7:$AC$8,"Nb de points",$J14:$AC14)) -> 0 | AM14: =SUM(AK14:AL14,AI14) -> 0 | AN14: 22 | AO14: =IFERROR(IF(IF(OR(AI14>=2,AJ14>=8,AND(AI14=1,AJ14>=4)),0,IF(OR(AND(AI14=1,AJ14<4),AND(AI14=0,AJ14>=4,AJ14<8)),50%,100%))*(AN14-AM14)/AN14=0,-100%,IF(OR(AI14>=2,AJ14>=8,AND(AI14=1,AJ14>=4)),0,IF(OR(AND(AI14=1,AJ14<4),AND(AI14=0,AJ14>=4,AJ14<8)),50%,100%))*(AN14-AM14)/AN14-1),"") -> 0 | AP14: =IFERROR((H14*AF14/100)*(1+AO14),"") | AR14: =IFERROR(VLOOKUP(B14,OBJECTIFS!$C$76:$E$137,2,FALSE),0) -> 0 | AS14: =IFERROR(VLOOKUP(B14,OBJECTIFS!$H$76:$J$137,2,FALSE),0) -> 0 | AT14: =IFERROR(VLOOKUP(B14,OBJECTIFS!$C$142:$E$203,2,FALSE),0) -> 0 | AU14: =IFERROR(VLOOKUP(B14,OBJECTIFS!$H$142:$J$203,2,FALSE),0) -> 0 | AV14: =IFERROR(VLOOKUP(B14,OBJECTIFS!$F$208:$H$269,3,FALSE),0) -> 0 | AW14: =IF($B$5="interne",IF($AR$6="prime de langue",IF(AH14>=191,SUM(AS14:AV14,AR14/191*191),SUM(AS14:AV14,AR14/191*AH14)),IF($AS$6="prime de langue",IF(AH14>=191,SUM(AR14,AT14,AU14,AV14,AS14/191*191),SUM(AR14,AT14,AU14,AV14,AS14/191*AH14)),IF($AT$6="prime de langue",IF(AH14>=191,SUM(AR14,AS14,AU14,AV14,AT14/191*191),SUM(AR14,AS14,AU14,AV14,AT14/191*AH14)),IF($AU$6="prime de langue",IF(AH14>=191,SUM(AR14,AT14,AV14,AS14,AU14/191*191),SUM(AR14,AT14,AV14,AS14,AU14/191*AH14)),SUM(AR14:AV14))))),IF($AR$6="prime de langue",IF(AH14>=176,SUM(AS14:AV14,AR14/176*176),SUM(AS14:AV14,AR14/176*AH14)),IF($AS$6="prime de langue",IF(AH14>=176,SUM(AR14,AT14,AU14,AV14,AS14/176*176),SUM(AR14,AT14,AU14,AV14,AS14/176*AH14)),IF($AT$6="prime de langue",IF(AH14>=176,SUM(AR14,AS14,AU14,AV14,AT14/176*176),SUM(AR14,AS14,AU14,AV14,AT14/176*AH14)),IF($AU$6="prime de langue",IF(AH14>=176,SUM(AR14,AT14,AV14,AS14,AU14/176*176),SUM(AR14,AT14,AV14,AS14,AU14/176*AH14)),SUM(AR14:AV14)))))) -> 0 | AY14: =IFERROR(((H14*AF14/100)*(1+AO14)+AW14),"") | BA14: =IFERROR(IF(OR(AI14>=2,AJ14>=8,AND(AI14=1,AJ14>=4)),0,IF(OR(AND(AI14=1,AJ14<4),AND(AI14=0,AJ14>=4,AJ14<8)),0.5,1))*AF14*(AN14-AM14)/AN14,"") -> 0 | BB14: =IF(BC14="","","è") | BC14: =IF(BA14=0,"",IF(BA14>=MAX($BA$9:$BA$216),A14,""))
H15: =IF(OR(D15="",F15="",A15=""),"",IF(E15="oui",0,IF(D15=OBJECTIFS!$C$45,VLOOKUP(F15,OBJECTIFS!$C$9:$D$11,2,FALSE),IF(D15=OBJECTIFS!$C$46,VLOOKUP(F15,OBJECTIFS!$C$16:$D$18,2,FALSE),IF(D15=OBJECTIFS!$C$47,VLOOKUP(F15,OBJECTIFS!$C$23:$D$25,2,FALSE),IF(D15=OBJECTIFS!$C$48,VLOOKUP(F15,OBJECTIFS!$C$30:$D$32,2,FALSE),IF(D15=OBJECTIFS!$C$49,VLOOKUP(F15,OBJECTIFS!$C$37:$D$39,2,FALSE)))))))) | K15: =IF(OR($A15="",$D15="",J15=""),"",SUMIFS(OBJECTIFS!E$9:E$39,OBJECTIFS!$A$9:$A$39,$D15,OBJECTIFS!$C$9:$C$39,$F15)) | L15: =IF(OR(AND($D15=OBJECTIFS!$B$6,OBJECTIFS!E$8="dmt"),AND($D15=OBJECTIFS!$B$13,OBJECTIFS!$E$15="dmt"),AND($D15=OBJECTIFS!$B$20,OBJECTIFS!$E$22="dmt"),AND($D15=OBJECTIFS!$B$27,OBJECTIFS!$E$29="dmt"),AND($D15=OBJECTIFS!$B$34,OBJECTIFS!$E$36="dmt"),AND($D15=OBJECTIFS!$B$6,OBJECTIFS!$E$8="taux de chute"),AND($D15=OBJECTIFS!$B$13,OBJECTIFS!$E$15="taux de chute"),AND($D15=OBJECTIFS!$B$20,OBJECTIFS!$E$22="taux de chute"),AND($D15=OBJECTIFS!$B$27,OBJECTIFS!$E$29="taux de chute"),AND($D15=OBJECTIFS!$B$34,OBJECTIFS!$E$36="taux de chute")),IFERROR(K15/J15,""),IFERROR(J15/K15,"")) | M15: =IFERROR(IF(OR(J15="",K15="",L15=""),0,IF(L15<OBJECTIFS!$E$56,0,IF(L15<OBJECTIFS!$G$56,M$8*OBJECTIFS!$F$60,IF(L15<OBJECTIFS!$I$56,M$8*OBJECTIFS!$H$60,M$8)))),0) -> 0 | O15: =IF(OR($A15="",$D15="",N15=""),"",SUMIFS(OBJECTIFS!F$9:F$39,OBJECTIFS!$A$9:$A$39,$D15,OBJECTIFS!$C$9:$C$39,$F15)) | P15: =IF(OR(AND($D15=OBJECTIFS!$B$6,OBJECTIFS!$F$8="dmt"),AND($D15=OBJECTIFS!$B$13,OBJECTIFS!$F$15="dmt"),AND($D15=OBJECTIFS!$B$20,OBJECTIFS!$F$22="dmt"),AND($D15=OBJECTIFS!$B$27,OBJECTIFS!$F$29="dmt"),AND($D15=OBJECTIFS!$B$34,OBJECTIFS!$F$36="dmt"),AND($D15=OBJECTIFS!$B$6,OBJECTIFS!$F$8="taux de chute"),AND($D15=OBJECTIFS!$B$13,OBJECTIFS!$F$15="taux de chute"),AND($D15=OBJECTIFS!$B$20,OBJECTIFS!$F$22="taux de chute"),AND($D15=OBJECTIFS!$B$27,OBJECTIFS!$F$29="taux de chute"),AND($D15=OBJECTIFS!$B$34,OBJECTIFS!$F$36="taux de chute")),IFERROR(O15/N15,""),IFERROR(N15/O15,"")) | Q15: =IFERROR(IF(OR(N15="",O15="",P15=""),0,IF(P15<OBJECTIFS!$E$56,0,IF(P15<OBJECTIFS!$G$56,Q$8*OBJECTIFS!$F$60,IF(P15<OBJECTIFS!$I$56,Q$8*OBJECTIFS!$H$60,Q$8)))),0) -> 0 | S15: =IF(OR($A15="",$D15="",R15=""),"",SUMIFS(OBJECTIFS!G$9:G$39,OBJECTIFS!$A$9:$A$39,$D15,OBJECTIFS!$C$9:$C$39,$F15)) | T15: =IF(OR(AND($D15=OBJECTIFS!$B$6,OBJECTIFS!G$8="dmt"),AND($D15=OBJECTIFS!$B$13,OBJECTIFS!$G$15="dmt"),AND($D15=OBJECTIFS!$B$20,OBJECTIFS!$G$22="dmt"),AND($D15=OBJECTIFS!$B$27,OBJECTIFS!$G$29="dmt"),AND($D15=OBJECTIFS!$B$34,OBJECTIFS!$G$36="dmt"),AND($D15=OBJECTIFS!$B$6,OBJECTIFS!$G$8="taux de chute"),AND($D15=OBJECTIFS!$B$13,OBJECTIFS!$G$15="taux de chute"),AND($D15=OBJECTIFS!$B$20,OBJECTIFS!$G$22="taux de chute"),AND($D15=OBJECTIFS!$B$27,OBJECTIFS!$G$29="taux de chute"),AND($D15=OBJECTIFS!$B$34,OBJECTIFS!$G$36="taux de chute")),IFERROR(S15/R15,""),IFERROR(R15/S15,"")) | U15: =IFERROR(IF(OR(R15="",S15="",T15=""),0,IF(T15<OBJECTIFS!$E$56,0,IF(T15<OBJECTIFS!$G$56,U$8*OBJECTIFS!$F$60,IF(T15<OBJECTIFS!$I$56,U$8*OBJECTIFS!$H$60,U$8)))),0) -> 0 | W15: =IF(OR($A15="",$D15="",V15=""),"",SUMIFS(OBJECTIFS!H$9:H$39,OBJECTIFS!$A$9:$A$39,$D15,OBJECTIFS!$C$9:$C$39,$F15)) | X15: =IF(OR(AND($D15=OBJECTIFS!$B$6,OBJECTIFS!H$8="dmt"),AND($D15=OBJECTIFS!$B$13,OBJECTIFS!$H$15="dmt"),AND($D15=OBJECTIFS!$B$20,OBJECTIFS!$H$22="dmt"),AND($D15=OBJECTIFS!$B$27,OBJECTIFS!$H$29="dmt"),AND($D15=OBJECTIFS!$B$34,OBJECTIFS!$H$36="dmt"),AND($D15=OBJECTIFS!$B$6,OBJECTIFS!$H$8="taux de chute"),AND($D15=OBJECTIFS!$B$13,OBJECTIFS!$H$15="taux de chute"),AND($D15=OBJECTIFS!$B$20,OBJECTIFS!$H$22="taux de chute"),AND($D15=OBJECTIFS!$B$27,OBJECTIFS!$H$29="taux de chute"),AND($D15=OBJECTIFS!$B$34,OBJECTIFS!$H$36="taux de chute")),IFERROR(W15/V15,""),IFERROR(V15/W15,"")) | Y15: =IFERROR(IF(OR(V15="",W15="",X15=""),0,IF(X15<OBJECTIFS!$E$56,0,IF(X15<OBJECTIFS!$G$56,Y$8*OBJECTIFS!$F$60,IF(X15<OBJECTIFS!$I$56,Y$8*OBJECTIFS!$H$60,Y$8)))),0) -> 0 | AA15: =IF(OR($A15="",$D15="",Z15=""),"",SUMIFS(OBJECTIFS!I$9:I$39,OBJECTIFS!$A$9:$A$39,$D15,OBJECTIFS!$C$9:$C$39,$F15)) | AB15: =IF(OR(AND($D15=OBJECTIFS!$B$6,OBJECTIFS!I$8="dmt"),AND($D15=OBJECTIFS!$B$13,OBJECTIFS!$I$15="dmt"),AND($D15=OBJECTIFS!$B$20,OBJECTIFS!$I$22="dmt"),AND($D15=OBJECTIFS!$B$27,OBJECTIFS!$I$29="dmt"),AND($D15=OBJECTIFS!$B$34,OBJECTIFS!$I$36="dmt"),AND($D15=OBJECTIFS!$B$6,OBJECTIFS!$I$8="taux de chute"),AND($D15=OBJECTIFS!$B$13,OBJECTIFS!$I$15="taux de chute"),AND($D15=OBJECTIFS!$B$20,OBJECTIFS!$I$22="taux de chute"),AND($D15=OBJECTIFS!$B$27,OBJECTIFS!$I$29="taux de chute"),AND($D15=OBJECTIFS!$B$34,OBJECTIFS!$I$36="taux de chute")),IFERROR(AA15/Z15,""),IFERROR(Z15/AA15,"")) | AC15: =IFERROR(IF(OR(Z15="",AA15="",AB15=""),0,IF(AB15<OBJECTIFS!$E$56,0,IF(AB15<OBJECTIFS!$G$56,AC$8*OBJECTIFS!$F$60,IF(AB15<OBJECTIFS!$I$56,AC$8*OBJECTIFS!$H$60,AC$8)))),0) -> 0 | AF15: =IF(AD15>=1,0,SUMIF($J$7:$AC$8,"Nb de points",$J15:$AC15)) -> 0 | AM15: =SUM(AK15:AL15,AI15) -> 0 | AN15: 22 | AO15: =IFERROR(IF(IF(OR(AI15>=2,AJ15>=8,AND(AI15=1,AJ15>=4)),0,IF(OR(AND(AI15=1,AJ15<4),AND(AI15=0,AJ15>=4,AJ15<8)),50%,100%))*(AN15-AM15)/AN15=0,-100%,IF(OR(AI15>=2,AJ15>=8,AND(AI15=1,AJ15>=4)),0,IF(OR(AND(AI15=1,AJ15<4),AND(AI15=0,AJ15>=4,AJ15<8)),50%,100%))*(AN15-AM15)/AN15-1),"") -> 0 | AP15: =IFERROR((H15*AF15/100)*(1+AO15),"") | AR15: =IFERROR(VLOOKUP(B15,OBJECTIFS!$C$76:$E$137,2,FALSE),0) -> 0 | AS15: =IFERROR(VLOOKUP(B15,OBJECTIFS!$H$76:$J$137,2,FALSE),0) -> 0 | AT15: =IFERROR(VLOOKUP(B15,OBJECTIFS!$C$142:$E$203,2,FALSE),0) -> 0 | AU15: =IFERROR(VLOOKUP(B15,OBJECTIFS!$H$142:$J$203,2,FALSE),0) -> 0 | AV15: =IFERROR(VLOOKUP(B15,OBJECTIFS!$F$208:$H$269,3,FALSE),0) -> 0 | AW15: =IF($B$5="interne",IF($AR$6="prime de langue",IF(AH15>=191,SUM(AS15:AV15,AR15/191*191),SUM(AS15:AV15,AR15/191*AH15)),IF($AS$6="prime de langue",IF(AH15>=191,SUM(AR15,AT15,AU15,AV15,AS15/191*191),SUM(AR15,AT15,AU15,AV15,AS15/191*AH15)),IF($AT$6="prime de langue",IF(AH15>=191,SUM(AR15,AS15,AU15,AV15,AT15/191*191),SUM(AR15,AS15,AU15,AV15,AT15/191*AH15)),IF($AU$6="prime de langue",IF(AH15>=191,SUM(AR15,AT15,AV15,AS15,AU15/191*191),SUM(AR15,AT15,AV15,AS15,AU15/191*AH15)),SUM(AR15:AV15))))),IF($AR$6="prime de langue",IF(AH15>=176,SUM(AS15:AV15,AR15/176*176),SUM(AS15:AV15,AR15/176*AH15)),IF($AS$6="prime de langue",IF(AH15>=176,SUM(AR15,AT15,AU15,AV15,AS15/176*176),SUM(AR15,AT15,AU15,AV15,AS15/176*AH15)),IF($AT$6="prime de langue",IF(AH15>=176,SUM(AR15,AS15,AU15,AV15,AT15/176*176),SUM(AR15,AS15,AU15,AV15,AT15/176*AH15)),IF($AU$6="prime de langue",IF(AH15>=176,SUM(AR15,AT15,AV15,AS15,AU15/176*176),SUM(AR15,AT15,AV15,AS15,AU15/176*AH15)),SUM(AR15:AV15)))))) -> 0 | AY15: =IFERROR(((H15*AF15/100)*(1+AO15)+AW15),"") | BA15: =IFERROR(IF(OR(AI15>=2,AJ15>=8,AND(AI15=1,AJ15>=4)),0,IF(OR(AND(AI15=1,AJ15<4),AND(AI15=0,AJ15>=4,AJ15<8)),0.5,1))*AF15*(AN15-AM15)/AN15,"") -> 0 | BB15: =IF(BC15="","","è") | BC15: =IF(BA15=0,"",IF(BA15>=MAX($BA$9:$BA$216),A15,""))
H16: =IF(OR(D16="",F16="",A16=""),"",IF(E16="oui",0,IF(D16=OBJECTIFS!$C$45,VLOOKUP(F16,OBJECTIFS!$C$9:$D$11,2,FALSE),IF(D16=OBJECTIFS!$C$46,VLOOKUP(F16,OBJECTIFS!$C$16:$D$18,2,FALSE),IF(D16=OBJECTIFS!$C$47,VLOOKUP(F16,OBJECTIFS!$C$23:$D$25,2,FALSE),IF(D16=OBJECTIFS!$C$48,VLOOKUP(F16,OBJECTIFS!$C$30:$D$32,2,FALSE),IF(D16=OBJECTIFS!$C$49,VLOOKUP(F16,OBJECTIFS!$C$37:$D$39,2,FALSE)))))))) | K16: =IF(OR($A16="",$D16="",J16=""),"",SUMIFS(OBJECTIFS!E$9:E$39,OBJECTIFS!$A$9:$A$39,$D16,OBJECTIFS!$C$9:$C$39,$F16)) | L16: =IF(OR(AND($D16=OBJECTIFS!$B$6,OBJECTIFS!E$8="dmt"),AND($D16=OBJECTIFS!$B$13,OBJECTIFS!$E$15="dmt"),AND($D16=OBJECTIFS!$B$20,OBJECTIFS!$E$22="dmt"),AND($D16=OBJECTIFS!$B$27,OBJECTIFS!$E$29="dmt"),AND($D16=OBJECTIFS!$B$34,OBJECTIFS!$E$36="dmt"),AND($D16=OBJECTIFS!$B$6,OBJECTIFS!$E$8="taux de chute"),AND($D16=OBJECTIFS!$B$13,OBJECTIFS!$E$15="taux de chute"),AND($D16=OBJECTIFS!$B$20,OBJECTIFS!$E$22="taux de chute"),AND($D16=OBJECTIFS!$B$27,OBJECTIFS!$E$29="taux de chute"),AND($D16=OBJECTIFS!$B$34,OBJECTIFS!$E$36="taux de chute")),IFERROR(K16/J16,""),IFERROR(J16/K16,"")) | M16: =IFERROR(IF(OR(J16="",K16="",L16=""),0,IF(L16<OBJECTIFS!$E$56,0,IF(L16<OBJECTIFS!$G$56,M$8*OBJECTIFS!$F$60,IF(L16<OBJECTIFS!$I$56,M$8*OBJECTIFS!$H$60,M$8)))),0) -> 0 | O16: =IF(OR($A16="",$D16="",N16=""),"",SUMIFS(OBJECTIFS!F$9:F$39,OBJECTIFS!$A$9:$A$39,$D16,OBJECTIFS!$C$9:$C$39,$F16)) | P16: =IF(OR(AND($D16=OBJECTIFS!$B$6,OBJECTIFS!$F$8="dmt"),AND($D16=OBJECTIFS!$B$13,OBJECTIFS!$F$15="dmt"),AND($D16=OBJECTIFS!$B$20,OBJECTIFS!$F$22="dmt"),AND($D16=OBJECTIFS!$B$27,OBJECTIFS!$F$29="dmt"),AND($D16=OBJECTIFS!$B$34,OBJECTIFS!$F$36="dmt"),AND($D16=OBJECTIFS!$B$6,OBJECTIFS!$F$8="taux de chute"),AND($D16=OBJECTIFS!$B$13,OBJECTIFS!$F$15="taux de chute"),AND($D16=OBJECTIFS!$B$20,OBJECTIFS!$F$22="taux de chute"),AND($D16=OBJECTIFS!$B$27,OBJECTIFS!$F$29="taux de chute"),AND($D16=OBJECTIFS!$B$34,OBJECTIFS!$F$36="taux de chute")),IFERROR(O16/N16,""),IFERROR(N16/O16,"")) | Q16: =IFERROR(IF(OR(N16="",O16="",P16=""),0,IF(P16<OBJECTIFS!$E$56,0,IF(P16<OBJECTIFS!$G$56,Q$8*OBJECTIFS!$F$60,IF(P16<OBJECTIFS!$I$56,Q$8*OBJECTIFS!$H$60,Q$8)))),0) -> 0 | S16: =IF(OR($A16="",$D16="",R16=""),"",SUMIFS(OBJECTIFS!G$9:G$39,OBJECTIFS!$A$9:$A$39,$D16,OBJECTIFS!$C$9:$C$39,$F16)) | T16: =IF(OR(AND($D16=OBJECTIFS!$B$6,OBJECTIFS!G$8="dmt"),AND($D16=OBJECTIFS!$B$13,OBJECTIFS!$G$15="dmt"),AND($D16=OBJECTIFS!$B$20,OBJECTIFS!$G$22="dmt"),AND($D16=OBJECTIFS!$B$27,OBJECTIFS!$G$29="dmt"),AND($D16=OBJECTIFS!$B$34,OBJECTIFS!$G$36="dmt"),AND($D16=OBJECTIFS!$B$6,OBJECTIFS!$G$8="taux de chute"),AND($D16=OBJECTIFS!$B$13,OBJECTIFS!$G$15="taux de chute"),AND($D16=OBJECTIFS!$B$20,OBJECTIFS!$G$22="taux de chute"),AND($D16=OBJECTIFS!$B$27,OBJECTIFS!$G$29="taux de chute"),AND($D16=OBJECTIFS!$B$34,OBJECTIFS!$G$36="taux de chute")),IFERROR(S16/R16,""),IFERROR(R16/S16,"")) | U16: =IFERROR(IF(OR(R16="",S16="",T16=""),0,IF(T16<OBJECTIFS!$E$56,0,IF(T16<OBJECTIFS!$G$56,U$8*OBJECTIFS!$F$60,IF(T16<OBJECTIFS!$I$56,U$8*OBJECTIFS!$H$60,U$8)))),0) -> 0 | W16: =IF(OR($A16="",$D16="",V16=""),"",SUMIFS(OBJECTIFS!H$9:H$39,OBJECTIFS!$A$9:$A$39,$D16,OBJECTIFS!$C$9:$C$39,$F16)) | X16: =IF(OR(AND($D16=OBJECTIFS!$B$6,OBJECTIFS!H$8="dmt"),AND($D16=OBJECTIFS!$B$13,OBJECTIFS!$H$15="dmt"),AND($D16=OBJECTIFS!$B$20,OBJECTIFS!$H$22="dmt"),AND($D16=OBJECTIFS!$B$27,OBJECTIFS!$H$29="dmt"),AND($D16=OBJECTIFS!$B$34,OBJECTIFS!$H$36="dmt"),AND($D16=OBJECTIFS!$B$6,OBJECTIFS!$H$8="taux de chute"),AND($D16=OBJECTIFS!$B$13,OBJECTIFS!$H$15="taux de chute"),AND($D16=OBJECTIFS!$B$20,OBJECTIFS!$H$22="taux de chute"),AND($D16=OBJECTIFS!$B$27,OBJECTIFS!$H$29="taux de chute"),AND($D16=OBJECTIFS!$B$34,OBJECTIFS!$H$36="taux de chute")),IFERROR(W16/V16,""),IFERROR(V16/W16,"")) | Y16: =IFERROR(IF(OR(V16="",W16="",X16=""),0,IF(X16<OBJECTIFS!$E$56,0,IF(X16<OBJECTIFS!$G$56,Y$8*OBJECTIFS!$F$60,IF(X16<OBJECTIFS!$I$56,Y$8*OBJECTIFS!$H$60,Y$8)))),0) -> 0 | AA16: =IF(OR($A16="",$D16="",Z16=""),"",SUMIFS(OBJECTIFS!I$9:I$39,OBJECTIFS!$A$9:$A$39,$D16,OBJECTIFS!$C$9:$C$39,$F16)) | AB16: =IF(OR(AND($D16=OBJECTIFS!$B$6,OBJECTIFS!I$8="dmt"),AND($D16=OBJECTIFS!$B$13,OBJECTIFS!$I$15="dmt"),AND($D16=OBJECTIFS!$B$20,OBJECTIFS!$I$22="dmt"),AND($D16=OBJECTIFS!$B$27,OBJECTIFS!$I$29="dmt"),AND($D16=OBJECTIFS!$B$34,OBJECTIFS!$I$36="dmt"),AND($D16=OBJECTIFS!$B$6,OBJECTIFS!$I$8="taux de chute"),AND($D16=OBJECTIFS!$B$13,OBJECTIFS!$I$15="taux de chute"),AND($D16=OBJECTIFS!$B$20,OBJECTIFS!$I$22="taux de chute"),AND($D16=OBJECTIFS!$B$27,OBJECTIFS!$I$29="taux de chute"),AND($D16=OBJECTIFS!$B$34,OBJECTIFS!$I$36="taux de chute")),IFERROR(AA16/Z16,""),IFERROR(Z16/AA16,"")) | AC16: =IFERROR(IF(OR(Z16="",AA16="",AB16=""),0,IF(AB16<OBJECTIFS!$E$56,0,IF(AB16<OBJECTIFS!$G$56,AC$8*OBJECTIFS!$F$60,IF(AB16<OBJECTIFS!$I$56,AC$8*OBJECTIFS!$H$60,AC$8)))),0) -> 0 | AF16: =IF(AD16>=1,0,SUMIF($J$7:$AC$8,"Nb de points",$J16:$AC16)) -> 0 | AM16: =SUM(AK16:AL16,AI16) -> 0 | AN16: 22 | AO16: =IFERROR(IF(IF(OR(AI16>=2,AJ16>=8,AND(AI16=1,AJ16>=4)),0,IF(OR(AND(AI16=1,AJ16<4),AND(AI16=0,AJ16>=4,AJ16<8)),50%,100%))*(AN16-AM16)/AN16=0,-100%,IF(OR(AI16>=2,AJ16>=8,AND(AI16=1,AJ16>=4)),0,IF(OR(AND(AI16=1,AJ16<4),AND(AI16=0,AJ16>=4,AJ16<8)),50%,100%))*(AN16-AM16)/AN16-1),"") -> 0 | AP16: =IFERROR((H16*AF16/100)*(1+AO16),"") | AR16: =IFERROR(VLOOKUP(B16,OBJECTIFS!$C$76:$E$137,2,FALSE),0) -> 0 | AS16: =IFERROR(VLOOKUP(B16,OBJECTIFS!$H$76:$J$137,2,FALSE),0) -> 0 | AT16: =IFERROR(VLOOKUP(B16,OBJECTIFS!$C$142:$E$203,2,FALSE),0) -> 0 | AU16: =IFERROR(VLOOKUP(B16,OBJECTIFS!$H$142:$J$203,2,FALSE),0) -> 0 | AV16: =IFERROR(VLOOKUP(B16,OBJECTIFS!$F$208:$H$269,3,FALSE),0) -> 0 | AW16: =IF($B$5="interne",IF($AR$6="prime de langue",IF(AH16>=191,SUM(AS16:AV16,AR16/191*191),SUM(AS16:AV16,AR16/191*AH16)),IF($AS$6="prime de langue",IF(AH16>=191,SUM(AR16,AT16,AU16,AV16,AS16/191*191),SUM(AR16,AT16,AU16,AV16,AS16/191*AH16)),IF($AT$6="prime de langue",IF(AH16>=191,SUM(AR16,AS16,AU16,AV16,AT16/191*191),SUM(AR16,AS16,AU16,AV16,AT16/191*AH16)),IF($AU$6="prime de langue",IF(AH16>=191,SUM(AR16,AT16,AV16,AS16,AU16/191*191),SUM(AR16,AT16,AV16,AS16,AU16/191*AH16)),SUM(AR16:AV16))))),IF($AR$6="prime de langue",IF(AH16>=176,SUM(AS16:AV16,AR16/176*176),SUM(AS16:AV16,AR16/176*AH16)),IF($AS$6="prime de langue",IF(AH16>=176,SUM(AR16,AT16,AU16,AV16,AS16/176*176),SUM(AR16,AT16,AU16,AV16,AS16/176*AH16)),IF($AT$6="prime de langue",IF(AH16>=176,SUM(AR16,AS16,AU16,AV16,AT16/176*176),SUM(AR16,AS16,AU16,AV16,AT16/176*AH16)),IF($AU$6="prime de langue",IF(AH16>=176,SUM(AR16,AT16,AV16,AS16,AU16/176*176),SUM(AR16,AT16,AV16,AS16,AU16/176*AH16)),SUM(AR16:AV16)))))) -> 0 | AY16: =IFERROR(((H16*AF16/100)*(1+AO16)+AW16),"") | BA16: =IFERROR(IF(OR(AI16>=2,AJ16>=8,AND(AI16=1,AJ16>=4)),0,IF(OR(AND(AI16=1,AJ16<4),AND(AI16=0,AJ16>=4,AJ16<8)),0.5,1))*AF16*(AN16-AM16)/AN16,"") -> 0 | BB16: =IF(BC16="","","è") | BC16: =IF(BA16=0,"",IF(BA16>=MAX($BA$9:$BA$216),A16,""))
