Workbook
Name Matrice: OBJECTIFS!$C$45:$J$49

Sheet Cartouche
A5: CARTOUCHE
A7: DOCUMENT
A8: Référence | B8: MCC_S01_FEG-GRILLE PRIMES AGENT-PVCP NL APSO
A9: Intitulé | B9: Grille de prime agent pour PVCP NL APSO
A10: Qui le remplit | B10: Chef de projet
A11: Quand le remplir | B11: avant le 10 de chaque mois
A12: A qui l'envoyer | B12: Directeur Général, Directeur des Opérations, DRH, Responsable Service Administratif RH
A13: Diffusion | B13: Prod et service paie
A16: TITRES | C16: DESIGNATION | E16: FORMAT
A17: Manager | C17: Nom du manager responsable de l'équipe | E17: Texte
A18: Opération | C18: Nom de l'opération ( Liste de choix) | E18: Texte
A19: Matricule | C19: Le matricule de l'agent | E19: alpha numérique
A20: Statut | C20: Liste de choix des différents statuts agent | E20: Texte
A21: Montant Cible | C21: Le montant total possible de la prime | E21: Monétaire
A22: Productivité | C22: Engloble 3 indicateurs quantitatifs de l'activité | E22: Nombre
A23: Qualité | C23: Englobe 2 indicateurs qualitatifs de l'activité | E23: Nombre
A24: Satisfaction client | C24: Le nombre de réclamations sur agent : Elément déclencheur de la prime) | E24: Nombre
A25: Heures produites | C25: les heures produites par l'agent en M-1 | E25: Nombre
A26: Assiduité, Comportement & Prorata | C26: Absences, retards, congés … etc. (Plus les mesures disciplinaires) | E26: Nombre
A27: Malus (en %) | C27: Taux de malus appliqué à la totalité de la prime | E27: Pourcentage
... A32: SOURCE PLANILICATION | C32: préciser si la planification des ressources se fait à notre niveau (interne) ou par le client | E32: Texte
A51: TABLEAU DE REVISION
A53: DATE | B53: VERSION | C53: NATURE MODIFICATION | D53: REDACTEUR | E53: VERIFICATEUR | F53: APPROBATEUR
A54: 45200 | B54: 1 | C54: Création | D54: FATIH FATIMA ZAHRA | E54: FATIH FATIMA ZAHRA | F54: FATIH FATIMA ZAHRA

Sheet Variable
P1: Règles d'assiduité | Z1: En cas d'execo on choisit par ordre
A2: Auteur EG: | P2: 1 Absence injustifiée ou 4 Retards | U2: Moitié de la prime est perdue | Z2: 1 | AB2: Le statut le plus Haut
A3: Date émission EG: | P3: 2 Absences injustifiée ou 8 Retards ou sanction | U3: Totalité de la prime est perdue | Z3: 2 | AB3: La progression en nombre de points /mois précédent
P4: 1 réclamation client sur le mois | U4: Toute la prime est perdue | Z4: 3 | AB4: Le nombre moyen de points du dernier trimestre
A5: SOURCE PLANILICATION | B5: Interne
A6: Noms prénoms | B6: Matricule | C6: Manager | D6: Opération | E6: Sanction disciplinaire | F6: Statut | H6: Montant Cible | J6: Productivité | K6: Qualité | L6: Satisfaction client | N6: Nb de points avant l'assiduité | P6: Assiduité, Comportement & Prorata | W6: Malus (en %) | X6: Montant de la prime hors Super Bonus | Z6: Autres Primes | AI6: Montant Final de la prime | AK6: Nombre de points Final | AM6: L'agent du mois de l'activité
J7: =+OBJECTIFS!E5 -> CA | K7: =+OBJECTIFS!H5 -> Note qualité | L7: Réclamation client sur Agent | P7: Heures produites | Q7: Abs injust. | R7: Retards | S7: Abs just. | T7: Congé payé + CSS (en j) | U7: Nb de jours non travaillés | V7: Nb de jours ouvrés du mois | Z7: MISSION | AB7: Prime LANGUE | AC7: PRIME DE LANGUE Finale | AE7: =+IF(OBJECTIFS!G68="","BONUS 3",OBJECTIFS!G68) -> BONUS 3 | AF7: =+IF(OBJECTIFS!G69="","BONUS 4",OBJECTIFS!G69) -> BONUS 4 | AG7: SUPER BONUS VENTES
H9: =IFERROR(IF(OR(D9="",F9="",A9=""),"",IF(AND(E9="non",J9<165000),LOOKUP(J9,OBJECTIFS!$E$277:$E$398,OBJECTIFS!$F$277:$F$398),(((J9*3%)*10%)*10.25))),0) | N9: =IF(A9="",0,IF(K9="",0,IF(L9>=1,0,IF(K9<75%,100-(100*15%),IF(K9<80%,100-(100*10%),IF(K9<85%,100-(100*5%),100)))))) -> 0 | U9: =SUM(S9:T9,Q9) -> 0 | V9: 22 | W9: =IFERROR(IF(IF(OR(Q9>=2,R9>=8,AND(Q9=1,R9>=4)),0,IF(OR(AND(Q9=1,R9<4),AND(Q9=0,R9>=4,R9<8)),50%,100%))*(V9-(U9))/V9=0,-100%,IF(OR(Q9>=2,R9>=8,AND(Q9=1,R9>=4)),0,IF(OR(AND(Q9=1,R9<4),AND(Q9=0,R9>=4,R9<8)),50%,100%))*(V9-(U9))/V9-1),"") -> 0 | X9: =IFERROR((H9*N9/100)*(1+W9),"") | Z9: =IFERROR(VLOOKUP(B9,OBJECTIFS!$C$76:$E$137,2,FALSE),0) -> 0 | AB9: =IFERROR(VLOOKUP(B9,OBJECTIFS!$H$76:$J$137,2,FALSE),0) -> 0 | AC9: =IF($B$5="interne",AB9/191*P9,AB9/176*P9) -> 0 | AE9: =IFERROR(VLOOKUP(B9,OBJECTIFS!$C$142:$E$203,2,FALSE),0) -> 0 | AF9: =IFERROR(VLOOKUP(B9,OBJECTIFS!$H$142:$J$203,2,FALSE),0) -> 0 | AG9: =IFERROR(VLOOKUP(B9,OBJECTIFS!$F$208:$H$269,3,FALSE),0) -> 0 | AI9: =IFERROR(SUM(AE9:AG9,AC9,Z9,X9),"") -> 0 | AK9: =IFERROR(IF(OR(Q9>=2,R9>=8,AND(Q9=1,R9>=4)),0,IF(OR(AND(Q9=1,R9<4),AND(Q9=0,R9>=4,R9<8)),0.5,1))*N9*(V9-U9)/V9,"") -> 0 | AL9: =IF(AM9="","","è") | AM9: =IF(AK9=0,"",IF(AK9>=MAX($AK$9:$AK$79),A9,""))
H10: =IFERROR(IF(OR(D10="",F10="",A10=""),"",IF(AND(E10="non",J10<165000),LOOKUP(J10,OBJECTIFS!$E$277:$E$398,OBJECTIFS!$F$277:$F$398),(((J10*3%)*10%)*10.25))),0) | N10: =IF(A10="",0,IF(K10="",0,IF(L10>=1,0,IF(K10<75%,100-(100*15%),IF(K10<80%,100-(100*10%),IF(K10<85%,100-(100*5%),100)))))) -> 0 | U10: =SUM(S10:T10,Q10) -> 0 | V10: =V9 -> 22 | W10: =IFERROR(IF(IF(OR(Q10>=2,R10>=8,AND(Q10=1,R10>=4)),0,IF(OR(AND(Q10=1,R10<4),AND(Q10=0,R10>=4,R10<8)),50%,100%))*(V10-(U10))/V10=0,-100%,IF(OR(Q10>=2,R10>=8,AND(Q10=1,R10>=4)),0,IF(OR(AND(Q10=1,R10<4),AND(Q10=0,R10>=4,R10<8)),50%,100%))*(V10-(U10))/V10-1),"") -> 0 | X10: =IFERROR((H10*N10/100)*(1+W10),"") | Z10: =IFERROR(VLOOKUP(B10,OBJECTIFS!$C$76:$E$137,2,FALSE),0) -> 0 | AB10: =IFERROR(VLOOKUP(B10,OBJECTIFS!$H$76:$J$137,2,FALSE),0) -> 0 | AC10: =IF($B$5="interne",AB10/191*P10,AB10/176*P10) -> 0 | AE10: =IFERROR(VLOOKUP(B10,OBJECTIFS!$C$142:$E$203,2,FALSE),0) -> 0 | AF10: =IFERROR(VLOOKUP(B10,OBJECTIFS!$H$142:$J$203,2,FALSE),0) -> 0 | AG10: =IFERROR(VLOOKUP(B10,OBJECTIFS!$F$208:$H$269,3,FALSE),0) -> 0 | AI10: =IFERROR(SUM(AE10:AG10,AC10,Z10,X10),"") -> 0 | AK10: =IFERROR(IF(OR(Q10>=2,R10>=8,AND(Q10=1,R10>=4)),0,IF(OR(AND(Q10=1,R10<4),AND(Q10=0,R10>=4,R10<8)),0.5,1))*N10*(V10-U10)/V10,"") -> 0 | AL10: =IF(AM10="","","è") | AM10: =IF(AK10=0,"",IF(AK10>=MAX($AK$9:$AK$79),A10,""))
H11: =IFERROR(IF(OR(D11="",F11="",A11=""),"",IF(AND(E11="non",J11<165000),LOOKUP(J11,OBJECTIFS!$E$277:$E$398,OBJECTIFS!$F$277:$F$398),(((J11*3%)*10%)*10.25))),0) | N11: =IF(A11="",0,IF(K11="",0,IF(L11>=1,0,IF(K11<75%,100-(100*15%),IF(K11<80%,100-(100*10%),IF(K11<85%,100-(100*5%),100)))))) -> 0 | U11: =SUM(S11:T11,Q11) -> 0 | V11: =V10 -> 22 | W11: =IFERROR(IF(IF(OR(Q11>=2,R11>=8,AND(Q11=1,R11>=4)),0,IF(OR(AND(Q11=1,R11<4),AND(Q11=0,R11>=4,R11<8)),50%,100%))*(V11-(U11))/V11=0,-100%,IF(OR(Q11>=2,R11>=8,AND(Q11=1,R11>=4)),0,IF(OR(AND(Q11=1,R11<4),AND(Q11=0,R11>=4,R11<8)),50%,100%))*(V11-(U11))/V11-1),"") -> 0 | X11: =IFERROR((H11*N11/100)*(1+W11),"") | Z11: =IFERROR(VLOOKUP(B11,OBJECTIFS!$C$76:$E$137,2,FALSE),0) -> 0 | AB11: =IFERROR(VLOOKUP(B11,OBJECTIFS!$H$76:$J$137,2,FALSE),0) -> 0 | AC11: =IF($B$5="interne",AB11/191*P11,AB11/176*P11) -> 0 | AE11: =IFERROR(VLOOKUP(B11,OBJECTIFS!$C$142:$E$203,2,FALSE),0) -> 0 | AF11: =IFERROR(VLOOKUP(B11,OBJECTIFS!$H$142:$J$203,2,FALSE),0) -> 0 | AG11: =IFERROR(VLOOKUP(B11,OBJECTIFS!$F$208:$H$269,3,FALSE),0) -> 0 | AI11: =IFERROR(SUM(AE11:AG11,AC11,Z11,X11),"") -> 0 | AK11: =IFERROR(IF(OR(Q11>=2,R11>=8,AND(Q11=1,R11>=4)),0,IF(OR(AND(Q11=1,R11<4),AND(Q11=0,R11>=4,R11<8)),0.5,1))*N11*(V11-U11)/V11,"") -> 0 | AL11: =IF(AM11="","","è") | AM11: =IF(AK11=0,"",IF(AK11>=MAX($AK$9:$AK$78),A11,""))
H12: =IFERROR(IF(OR(D12="",F12="",A12=""),"",IF(AND(E12="non",J12<165000),LOOKUP(J12,OBJECTIFS!$E$277:$E$398,OBJECTIFS!$F$277:$F$398),(((J12*3%)*10%)*10.25))),0) | N12: =IF(A12="",0,IF(K12="",0,IF(L12>=1,0,IF(K12<75%,100-(100*15%),IF(K12<80%,100-(100*10%),IF(K12<85%,100-(100*5%),100)))))) -> 0 | U12: =SUM(S12:T12,Q12) -> 0 | V12: =V11 -> 22 | W12: =IFERROR(IF(IF(OR(Q12>=2,R12>=8,AND(Q12=1,R12>=4)),0,IF(OR(AND(Q12=1,R12<4),AND(Q12=0,R12>=4,R12<8)),50%,100%))*(V12-(U12))/V12=0,-100%,IF(OR(Q12>=2,R12>=8,AND(Q12=1,R12>=4)),0,IF(OR(AND(Q12=1,R12<4),AND(Q12=0,R12>=4,R12<8)),50%,100%))*(V12-(U12))/V12-1),"") -> 0 | X12: =IFERROR((H12*N12/100)*(1+W12),"") | Z12: =IFERROR(VLOOKUP(B12,OBJECTIFS!$C$76:$E$137,2,FALSE),0) -> 0 | AB12: =IFERROR(VLOOKUP(B12,OBJECTIFS!$H$76:$J$137,2,FALSE),0) -> 0 | AC12: =IF($B$5="interne",AB12/191*P12,AB12/176*P12) -> 0 | AE12: =IFERROR(VLOOKUP(B12,OBJECTIFS!$C$142:$E$203,2,FALSE),0) -> 0 | AF12: =IFERROR(VLOOKUP(B12,OBJECTIFS!$H$142:$J$203,2,FALSE),0) -> 0 | AG12: =IFERROR(VLOOKUP(B12,OBJECTIFS!$F$208:$H$269,3,FALSE),0) -> 0 | AI12: =IFERROR(SUM(AE12:AG12,AC12,Z12,X12),"") -> 0 | AK12: =IFERROR(IF(OR(Q12>=2,R12>=8,AND(Q12=1,R12>=4)),0,IF(OR(AND(Q12=1,R12<4),AND(Q12=0,R12>=4,R12<8)),0.5,1))*N12*(V12-U12)/V12,"") -> 0 | AL12: =IF(AM12="","","è") | AM12: =IF(AK12=0,"",IF(AK12>=MAX($AK$9:$AK$78),A12,""))
H13: =IFERROR(IF(OR(D13="",F13="",A13=""),"",IF(AND(E13="non",J13<165000),LOOKUP(J13,OBJECTIFS!$E$277:$E$398,OBJECTIFS!$F$277:$F$398),(((J13*3%)*10%)*10.25))),0) | N13: =IF(A13="",0,IF(K13="",0,IF(L13>=1,0,IF(K13<75%,100-(100*15%),IF(K13<80%,100-(100*10%),IF(K13<85%,100-(100*5%),100)))))) -> 0 | U13: =SUM(S13:T13,Q13) -> 0 | V13: =V12 -> 22 | W13: =IFERROR(IF(IF(OR(Q13>=2,R13>=8,AND(Q13=1,R13>=4)),0,IF(OR(AND(Q13=1,R13<4),AND(Q13=0,R13>=4,R13<8)),50%,100%))*(V13-(U13))/V13=0,-100%,IF(OR(Q13>=2,R13>=8,AND(Q13=1,R13>=4)),0,IF(OR(AND(Q13=1,R13<4),AND(Q13=0,R13>=4,R13<8)),50%,100%))*(V13-(U13))/V13-1),"") -> 0 | X13: =IFERROR((H13*N13/100)*(1+W13),"") | Z13: =IFERROR(VLOOKUP(B13,OBJECTIFS!$C$76:$E$137,2,FALSE),0) -> 0 | AB13: =IFERROR(VLOOKUP(B13,OBJECTIFS!$H$76:$J$137,2,FALSE),0) -> 0 | AC13: =IF($B$5="interne",AB13/191*P13,AB13/176*P13) -> 0 | AE13: =IFERROR(VLOOKUP(B13,OBJECTIFS!$C$142:$E$203,2,FALSE),0) -> 0 | AF13: =IFERROR(VLOOKUP(B13,OBJECTIFS!$H$142:$J$203,2,FALSE),0) -> 0 | AG13: =IFERROR(VLOOKUP(B13,OBJECTIFS!$F$208:$H$269,3,FALSE),0) -> 0 | AI13: =IFERROR(SUM(AE13:AG13,AC13,Z13,X13),"") -> 0 | AK13: =IFERROR(IF(OR(Q13>=2,R13>=8,AND(Q13=1,R13>=4)),0,IF(OR(AND(Q13=1,R13<4),AND(Q13=0,R13>=4,R13<8)),0.5,1))*N13*(V13-U13)/V13,"") -> 0 | AL13: =IF(AM13="","","è") | AM13: =IF(AK13=0,"",IF(AK13>=MAX($AK$9:$AK$78),A13,""))
H14: =IFERROR(IF(OR(D14="",F14="",A14=""),"",IF(AND(E14="non",J14<165000),LOOKUP(J14,OBJECTIFS!$E$277:$E$398,OBJECTIFS!$F$277:$F$398),(((J14*3%)*10%)*10.25))),0) | N14: =IF(A14="",0,IF(K14="",0,IF(L14>=1,0,IF(K14<75%,100-(100*15%),IF(K14<80%,100-(100*10%),IF(K14<85%,100-(100*5%),100)))))) -> 0 | U14: =SUM(S14:T14,Q14) -> 0 | V14: =V13 -> 22 | W14: =IFERROR(IF(IF(OR(Q14>=2,R14>=8,AND(Q14=1,R14>=4)),0,IF(OR(AND(Q14=1,R14<4),AND(Q14=0,R14>=4,R14<8)),50%,100%))*(V14-(U14))/V14=0,-100%,IF(OR(Q14>=2,R14>=8,AND(Q14=1,R14>=4)),0,IF(OR(AND(Q14=1,R14<4),AND(Q14=0,R14>=4,R14<8)),50%,100%))*(V14-(U14))/V14-1),"") -> 0 | X14: =IFERROR((H14*N14/100)*(1+W14),"") | Z14: =IFERROR(VLOOKUP(B14,OBJECTIFS!$C$76:$E$137,2,FALSE),0) -> 0 | AB14: =IFERROR(VLOOKUP(B14,OBJECTIFS!$H$76:$J$137,2,FALSE),0) -> 0 | AC14: =IF($B$5="interne",AB14/191*P14,AB14/176*P14) -> 0 | AE14: =IFERROR(VLOOKUP(B14,OBJECTIFS!$C$142:$E$203,2,FALSE),0) -> 0 | AF14: =IFERROR(VLOOKUP(B14,OBJECTIFS!$H$142:$J$203,2,FALSE),0) -> 0 | AG14: =IFERROR(VLOOKUP(B14,OBJECTIFS!$F$208:$H$269,3,FALSE),0) -> 0 | AI14: =IFERROR(SUM(AE14:AG14,AC14,Z14,X14),"") -> 0 | AK14: =IFERROR(IF(OR(Q14>=2,R14>=8,AND(Q14=1,R14>=4)),0,IF(OR(AND(Q14=1,R14<4),AND(Q14=0,R14>=4,R14<8)),0.5,1))*N14*(V14-U14)/V14,"") -> 0 | AL14: =IF(AM14="","","è") | AM14: =IF(AK14=0,"",IF(AK14>=MAX($AK$9:$AK$78),A14,""))
H15: =IFERROR(IF(OR(D15="",F15="",A15=""),"",IF(AND(E15="non",J15<165000),LOOKUP(J15,OBJECTIFS!$E$277:$E$398,OBJECTIFS!$F$277:$F$398),(((J15*3%)*10%)*10.25))),0) | N15: =IF(A15="",0,IF(K15="",0,IF(L15>=1,0,IF(K15<75%,100-(100*15%),IF(K15<80%,100-(100*10%),IF(K15<85%,100-(100*5%),100)))))) -> 0 | U15: =SUM(S15:T15,Q15) -> 0 | V15: =V14 -> 22 | W15: =IFERROR(IF(IF(OR(Q15>=2,R15>=8,AND(Q15=1,R15>=4)),0,IF(OR(AND(Q15=1,R15<4),AND(Q15=0,R15>=4,R15<8)),50%,100%))*(V15-(U15))/V15=0,-100%,IF(OR(Q15>=2,R15>=8,AND(Q15=1,R15>=4)),0,IF(OR(AND(Q15=1,R15<4),AND(Q15=0,R15>=4,R15<8)),50%,100%))*(V15-(U15))/V15-1),"") -> 0 | X15: =IFERROR((H15*N15/100)*(1+W15),"") | Z15: =IFERROR(VLOOKUP(B15,OBJECTIFS!$C$76:$E$137,2,FALSE),0) -> 0 | AB15: =IFERROR(VLOOKUP(B15,OBJECTIFS!$H$76:$J$137,2,FALSE),0) -> 0 | AC15: =IF($B$5="interne",AB15/191*P15,AB15/176*P15) -> 0 | AE15: =IFERROR(VLOOKUP(B15,OBJECTIFS!$C$142:$E$203,2,FALSE),0) -> 0 | AF15: =IFERROR(VLOOKUP(B15,OBJECTIFS!$H$142:$J$203,2,FALSE),0) -> 0 | AG15: =IFERROR(VLOOKUP(B15,OBJECTIFS!$F$208:$H$269,3,FALSE),0) -> 0 | AI15: =IFERROR(SUM(AE15:AG15,AC15,Z15,X15),"") -> 0 | AK15: =IFERROR(IF(OR(Q15>=2,R15>=8,AND(Q15=1,R15>=4)),0,IF(OR(AND(Q15=1,R15<4),AND(Q15=0,R15>=4,R15<8)),0.5,1))*N15*(V15-U15)/V15,"") -> 0 | AL15: =IF(AM15="","","è") | AM15: =IF(AK15=0,"",IF(AK15>=MAX($AK$9:$AK$78),A15,""))
H16: =IFERROR(IF(OR(D16="",F16="",A16=""),"",IF(AND(E16="non",J16<165000),LOOKUP(J16,OBJECTIFS!$E$277:$E$398,OBJECTIFS!$F$277:$F$398),(((J16*3%)*10%)*10.25))),0) | N16: =IF(A16="",0,IF(K16="",0,IF(L16>=1,0,IF(K16<75%,100-(100*15%),IF(K16<80%,100-(100*10%),IF(K16<85%,100-(100*5%),100)))))) -> 0 | U16: =SUM(S16:T16,Q16) -> 0 | V16: =V15 -> 22 | W16: =IFERROR(IF(IF(OR(Q16>=2,R16>=8,AND(Q16=1,R16>=4)),0,IF(OR(AND(Q16=1,R16<4),AND(Q16=0,R16>=4,R16<8)),50%,100%))*(V16-(U16))/V16=0,-100%,IF(OR(Q16>=2,R16>=8,AND(Q16=1,R16>=4)),0,IF(OR(AND(Q16=1,R16<4),AND(Q16=0,R16>=4,R16<8)),50%,100%))*(V16-(U16))/V16-1),"") -> 0 | X16: =IFERROR((H16*N16/100)*(1+W16),"") | Z16: =IFERROR(VLOOKUP(B16,OBJECTIFS!$C$76:$E$137,2,FALSE),0) -> 0 | AB16: =IFERROR(VLOOKUP(B16,OBJECTIFS!$H$76:$J$137,2,FALSE),0) -> 0 | AC16: =IF($B$5="interne",AB16/191*P16,AB16/176*P16) -> 0 | AE16: =IFERROR(VLOOKUP(B16,OBJECTIFS!$C$142:$E$203,2,FALSE),0) -> 0 | AF16: =IFERROR(VLOOKUP(B16,OBJECTIFS!$H$142:$J$203,2,FALSE),0) -> 0 | AG16: =IFERROR(VLOOKUP(B16,OBJECTIFS!$F$208:$H$269,3,FALSE),0) -> 0 | AI16: =IFERROR(SUM(AE16:AG16,AC16,Z16,X16),"") -> 0 | AK16: =IFERROR(IF(OR(Q16>=2,R16>=8,AND(Q16=1,R16>=4)),0,IF(OR(AND(Q16=1,R16<4),AND(Q16=0,R16>=4,R16<8)),0.5,1))*N16*(V16-U16)/V16,"") -> 0 | AL16: =IF(AM16="","","è") | AM16: =IF(AK16=0,"",IF(AK16>=MAX($AK$9:$AK$78),A16,""))
H17: =IFERROR(IF(OR(D17="",F17="",A17=""),"",IF(AND(E17="non",J17<165000),LOOKUP(J17,OBJECTIFS!$E$277:$E$398,OBJECTIFS!$F$277:$F$398),(((J17*3%)*10%)*10.25))),0) | N17: =IF(A17="",0,IF(K17="",0,IF(L17>=1,0,IF(K17<75%,100-(100*15%),IF(K17<80%,100-(100*10%),IF(K17<85%,100-(100*5%),100)))))) -> 0 | U17: =SUM(S17:T17,Q17) -> 0 | V17: =V16 -> 22 | W17: =IFERROR(IF(IF(OR(Q17>=2,R17>=8,AND(Q17=1,R17>=4)),0,IF(OR(AND(Q17=1,R17<4),AND(Q17=0,R17>=4,R17<8)),50%,100%))*(V17-(U17))/V17=0,-100%,IF(OR(Q17>=2,R17>=8,AND(Q17=1,R17>=4)),0,IF(OR(AND(Q17=1,R17<4),AND(Q17=0,R17>=4,R17<8)),50%,100%))*(V17-(U17))/V17-1),"") -> 0 | X17: =IFERROR((H17*N17/100)*(1+W17),"") | Z17: =IFERROR(VLOOKUP(B17,OBJECTIFS!$C$76:$E$137,2,FALSE),0) -> 0 | AB17: =IFERROR(VLOOKUP(B17,OBJECTIFS!$H$76:$J$137,2,FALSE),0) -> 0 | AC17: =IF($B$5="interne",AB17/191*P17,AB17/176*P17) -> 0 | AE17: =IFERROR(VLOOKUP(B17,OBJECTIFS!$C$142:$E$203,2,FALSE),0) -> 0 | AF17: =IFERROR(VLOOKUP(B17,OBJECTIFS!$H$142:$J$203,2,FALSE),0) -> 0 | AG17: =IFERROR(VLOOKUP(B17,OBJECTIFS!$F$208:$H$269,3,FALSE),0) -> 0 | AI17: =IFERROR(SUM(AE17:AG17,AC17,Z17,X17),"") -> 0 | AK17: =IFERROR(IF(OR(Q17>=2,R17>=8,AND(Q17=1,R17>=4)),0,IF(OR(AND(Q17=1,R17<4),AND(Q17=0,R17>=4,R17<8)),0.5,1))*N17*(V17-U17)/V17,"") -> 0 | AL17: =IF(AM17="","","è") | AM17: =IF(AK17=0,"",IF(AK17>=MAX($AK$9:$AK$78),A17,""))
H18: =IFERROR(IF(OR(D18="",F18="",A18=""),"",IF(AND(E18="non",J18<165000),LOOKUP(J18,OBJECTIFS!$E$277:$E$398,OBJECTIFS!$F$277:$F$398),(((J18*3%)*10%)*10.25))),0) | N18: =IF(A18="",0,IF(K18="",0,IF(L18>=1,0,IF(K18<75%,100-(100*15%),IF(K18<80%,100-(100*10%),IF(K18<85%,100-(100*5%),100)))))) -> 0 | U18: =SUM(S18:T18,Q18) -> 0 | V18: =V17 -> 22 | W18: =IFERROR(IF(IF(OR(Q18>=2,R18>=8,AND(Q18=1,R18>=4)),0,IF(OR(AND(Q18=1,R18<4),AND(Q18=0,R18>=4,R18<8)),50%,100%))*(V18-(U18))/V18=0,-100%,IF(OR(Q18>=2,R18>=8,AND(Q18=1,R18>=4)),0,IF(OR(AND(Q18=1,R18<4),AND(Q18=0,R18>=4,R18<8)),50%,100%))*(V18-(U18))/V18-1),"") -> 0 | X18: =IFERROR((H18*N18/100)*(1+W18),"") | Z18: =IFERROR(VLOOKUP(B18,OBJECTIFS!$C$76:$E$137,2,FALSE),0) -> 0 | AB18: =IFERROR(VLOOKUP(B18,OBJECTIFS!$H$76:$J$137,2,FALSE),0) -> 0 | AC18: =IF($B$5="interne",AB18/191*P18,AB18/176*P18) -> 0 | AE18: =IFERROR(VLOOKUP(B18,OBJECTIFS!$C$142:$E$203,2,FALSE),0) -> 0 | AF18: =IFERROR(VLOOKUP(B18,OBJECTIFS!$H$142:$J$203,2,FALSE),0) -> 0 | AG18: =IFERROR(VLOOKUP(B18,OBJECTIFS!$F$208:$H$269,3,FALSE),0) -> 0 | AI18: =IFERROR(SUM(AE18:AG18,AC18,Z18,X18),"") -> 0 | AK18: =IFERROR(IF(OR(Q18>=2,R18>=8,AND(Q18=1,R18>=4)),0,IF(OR(AND(Q18=1,R18<4),AND(Q18=0,R18>=4,R18<8)),0.5,1))*N18*(V18-U18)/V18,"") -> 0 | AL18: =IF(AM18="","","è") | AM18: =IF(AK18=0,"",IF(AK18>=MAX($AK$9:$AK$78),A18,""))
H19: =IFERROR(IF(OR(D19="",F19="",A19=""),"",IF(AND(E19="non",J19<165000),LOOKUP(J19,OBJECTIFS!$E$277:$E$398,OBJECTIFS!$F$277:$F$398),(((J19*3%)*10%)*10.25))),0) | N19: =IF(A19="",0,IF(K19="",0,IF(L19>=1,0,IF(K19<75%,100-(100*15%),IF(K19<80%,100-(100*10%),IF(K19<85%,100-(100*5%),100)))))) -> 0 | U19: =SUM(S19:T19,Q19) -> 0 | V19: =V18 -> 22 | W19: =IFERROR(IF(IF(OR(Q19>=2,R19>=8,AND(Q19=1,R19>=4)),0,IF(OR(AND(Q19=1,R19<4),AND(Q19=0,R19>=4,R19<8)),50%,100%))*(V19-(U19))/V19=0,-100%,IF(OR(Q19>=2,R19>=8,AND(Q19=1,R19>=4)),0,IF(OR(AND(Q19=1,R19<4),AND(Q19=0,R19>=4,R19<8)),50%,100%))*(V19-(U19))/V19-1),"") -> 0 | X19: =IFERROR((H19*N19/100)*(1+W19),"") | Z19: =IFERROR(VLOOKUP(B19,OBJECTIFS!$C$76:$E$137,2,FALSE),0) -> 0 | AB19: =IFERROR(VLOOKUP(B19,OBJECTIFS!$H$76:$J$137,2,FALSE),0) -> 0 | AC19: =IF($B$5="interne",AB19/191*P19,AB19/176*P19) -> 0 | AE19: =IFERROR(VLOOKUP(B19,OBJECTIFS!$C$142:$E$203,2,FALSE),0) -> 0 | AF19: =IFERROR(VLOOKUP(B19,OBJECTIFS!$H$142:$J$203,2,FALSE),0) -> 0 | AG19: =IFERROR(VLOOKUP(B19,OBJECTIFS!$F$208:$H$269,3,FALSE),0) -> 0 | AI19: =IFERROR(SUM(AE19:AG19,AC19,Z19,X19),"") -> 0 | AK19: =IFERROR(IF(OR(Q19>=2,R19>=8,AND(Q19=1,R19>=4)),0,IF(OR(AND(Q19=1,R19<4),AND(Q19=0,R19>=4,R19<8)),0.5,1))*N19*(V19-U19)/V19,"") -> 0 | AL19: =IF(AM19="","","è") | AM19: =IF(AK19=0,"",IF(AK19>=MAX($AK$9:$AK$78),A19,""))
H20: =IFERROR(IF(OR(D20="",F20="",A20=""),"",IF(AND(E20="non",J20<165000),LOOKUP(J20,OBJECTIFS!$E$277:$E$398,OBJECTIFS!$F$277:$F$398),(((J20*3%)*10%)*10.25))),0) | N20: =IF(A20="",0,IF(K20="",0,IF(L20>=1,0,IF(K20<75%,100-(100*15%),IF(K20<80%,100-(100*10%),IF(K20<85%,100-(100*5%),100)))))) -> 0 | U20: =SUM(S20:T20,Q20) -> 0 | V20: =V19 -> 22 | W20: =IFERROR(IF(IF(OR(Q20>=2,R20>=8,AND(Q20=1,R20>=4)),0,IF(OR(AND(Q20=1,R20<4),AND(Q20=0,R20>=4,R20<8)),50%,100%))*(V20-(U20))/V20=0,-100%,IF(OR(Q20>=2,R20>=8,AND(Q20=1,R20>=4)),0,IF(OR(AND(Q20=1,R20<4),AND(Q20=0,R20>=4,R20<8)),50%,100%))*(V20-(U20))/V20-1),"") -> 0 | X20: =IFERROR((H20*N20/100)*(1+W20),"") | Z20: =IFERROR(VLOOKUP(B20,OBJECTIFS!$C$76:$E$137,2,FALSE),0) -> 0 | AB20: =IFERROR(VLOOKUP(B20,OBJECTIFS!$H$76:$J$137,2,FALSE),0) -> 0 | AC20: =IF($B$5="interne",AB20/191*P20,AB20/176*P20) -> 0 | AE20: =IFERROR(VLOOKUP(B20,OBJECTIFS!$C$142:$E$203,2,FALSE),0) -> 0 | AF20: =IFERROR(VLOOKUP(B20,OBJECTIFS!$H$142:$J$203,2,FALSE),0) -> 0 | AG20: =IFERROR(VLOOKUP(B20,OBJECTIFS!$F$208:$H$269,3,FALSE),0) -> 0 | AI20: =IFERROR(SUM(AE20:AG20,AC20,Z20,X20),"") -> 0 | AK20: =IFERROR(IF(OR(Q20>=2,R20>=8,AND(Q20=1,R20>=4)),0,IF(OR(AND(Q20=1,R20<4),AND(Q20=0,R20>=4,R20<8)),0.5,1))*N20*(V20-U20)/V20,"") -> 0 | AL20: =IF(AM20="","","è") | AM20: =IF(AK20=0,"",IF(AK20>=MAX($AK$9:$AK$78),A20,""))
H21: =IFERROR(IF(OR(D21="",F21="",A21=""),"",IF(AND(E21="non",J21<165000),LOOKUP(J21,OBJECTIFS!$E$277:$E$398,OBJECTIFS!$F$277:$F$398),(((J21*3%)*10%)*10.25))),0) | N21: =IF(A21="",0,IF(K21="",0,IF(L21>=1,0,IF(K21<75%,100-(100*15%),IF(K21<80%,100-(100*10%),IF(K21<85%,100-(100*5%),100)))))) -> 0 | U21: =SUM(S21:T21,Q21) -> 0 | V21: =V20 -> 22 | W21: =IFERROR(IF(IF(OR(Q21>=2,R21>=8,AND(Q21=1,R21>=4)),0,IF(OR(AND(Q21=1,R21<4),AND(Q21=0,R21>=4,R21<8)),50%,100%))*(V21-(U21))/V21=0,-100%,IF(OR(Q21>=2,R21>=8,AND(Q21=1,R21>=4)),0,IF(OR(AND(Q21=1,R21<4),AND(Q21=0,R21>=4,R21<8)),50%,100%))*(V21-(U21))/V21-1),"") -> 0 | X21: =IFERROR((H21*N21/100)*(1+W21),"") | Z21: =IFERROR(VLOOKUP(B21,OBJECTIFS!$C$76:$E$137,2,FALSE),0) -> 0 | AB21: =IFERROR(VLOOKUP(B21,OBJECTIFS!$H$76:$J$137,2,FALSE),0) -> 0 | AC21: =IF($B$5="interne",AB21/191*P21,AB21/176*P21) -> 0 | AE21: =IFERROR(VLOOKUP(B21,OBJECTIFS!$C$142:$E$203,2,FALSE),0) -> 0 | AF21: =IFERROR(VLOOKUP(B21,OBJECTIFS!$H$142:$J$203,2,FALSE),0) -> 0 | AG21: =IFERROR(VLOOKUP(B21,OBJECTIFS!$F$208:$H$269,3,FALSE),0) -> 0 | AI21: =IFERROR(SUM(AE21:AG21,AC21,Z21,X21),"") -> 0 | AK21: =IFERROR(IF(OR(Q21>=2,R21>=8,AND(Q21=1,R21>=4)),0,IF(OR(AND(Q21=1,R21<4),AND(Q21=0,R21>=4,R21<8)),0.5,1))*N21*(V21-U21)/V21,"") -> 0 | AL21: =IF(AM21="","","è") | AM21: =IF(AK21=0,"",IF(AK21>=MAX($AK$9:$AK$78),A21,""))
H22: =IFERROR(IF(OR(D22="",F22="",A22=""),"",IF(AND(E22="non",J22<165000),LOOKUP(J22,OBJECTIFS!$E$277:$E$398,OBJECTIFS!$F$277:$F$398),(((J22*3%)*10%)*10.25))),0) | N22: =IF(A22="",0,IF(K22="",0,IF(L22>=1,0,IF(K22<75%,100-(100*15%),IF(K22<80%,100-(100*10%),IF(K22<85%,100-(100*5%),100)))))) -> 0 | U22: =SUM(S22:T22,Q22) -> 0 | V22: =V21 -> 22 | W22: =IFERROR(IF(IF(OR(Q22>=2,R22>=8,AND(Q22=1,R22>=4)),0,IF(OR(AND(Q22=1,R22<4),AND(Q22=0,R22>=4,R22<8)),50%,100%))*(V22-(U22))/V22=0,-100%,IF(OR(Q22>=2,R22>=8,AND(Q22=1,R22>=4)),0,IF(OR(AND(Q22=1,R22<4),AND(Q22=0,R22>=4,R22<8)),50%,100%))*(V22-(U22))/V22-1),"") -> 0 | X22: =IFERROR((H22*N22/100)*(1+W22),"") | Z22: =IFERROR(VLOOKUP(B22,OBJECTIFS!$C$76:$E$137,2,FALSE),0) -> 0 | AB22: =IFERROR(VLOOKUP(B22,OBJECTIFS!$H$76:$J$137,2,FALSE),0) -> 0 | AC22: =IF($B$5="interne",AB22/191*P22,AB22/176*P22) -> 0 | AE22: =IFERROR(VLOOKUP(B22,OBJECTIFS!$C$142:$E$203,2,FALSE),0) -> 0 | AF22: =IFERROR(VLOOKUP(B22,OBJECTIFS!$H$142:$J$203,2,FALSE),0) -> 0 | AG22: =IFERROR(VLOOKUP(B22,OBJECTIFS!$F$208:$H$269,3,FALSE),0) -> 0 | AI22: =IFERROR(SUM(AE22:AG22,AC22,Z22,X22),"") -> 0 | AK22: =IFERROR(IF(OR(Q22>=2,R22>=8,AND(Q22=1,R22>=4)),0,IF(OR(AND(Q22=1,R22<4),AND(Q22=0,R22>=4,R22<8)),0.5,1))*N22*(V22-U22)/V22,"") -> 0 | AL22: =IF(AM22="","","è") | AM22: =IF(AK22=0,"",IF(AK22>=MAX($AK$9:$AK$78),A22,""))
... H79: =IFERROR(IF(OR(D79="",F79="",A79=""),"",IF(AND(E79="non",J79<165000),LOOKUP(J79,OBJECTIFS!$E$277:$E$398,OBJECTIFS!$F$277:$F$398),(((J79*3%)*10%)*10.25))),0) | N79: =IF(A79="",0,IF(K79="",0,IF(L79>=1,0,IF(K79<75%,100-(100*15%),IF(K79<80%,100-(100*10%),IF(K79<85%,100-(100*5%),100)))))) -> 0 | U79: =SUM(S79:T79,Q79) -> 0 | V79: =V78 -> 22 | W79: =IFERROR(IF(IF(OR(Q79>=2,R79>=8,AND(Q79=1,R79>=4)),0,IF(OR(AND(Q79=1,R79<4),AND(Q79=0,R79>=4,R79<8)),50%,100%))*(V79-(U79))/V79=0,-100%,IF(OR(Q79>=2,R79>=8,AND(Q79=1,R79>=4)),0,IF(OR(AND(Q79=1,R79<4),AND(Q79=0,R79>=4,R79<8)),50%,100%))*(V79-(U79))/V79-1),"") -> 0 | X79: =IFERROR((H79*N79/100)*(1+W79),"") | Z79: =IFERROR(VLOOKUP(B79,OBJECTIFS!$C$76:$E$137,2,FALSE),0) -> 0 | AB79: =IFERROR(VLOOKUP(B79,OBJECTIFS!$H$76:$J$137,2,FALSE),0) -> 0 | AC79: =IF($B$5="interne",AB79/191*P79,AB79/176*P79) -> 0 | AE79: =IFERROR(VLOOKUP(B79,OBJECTIFS!$C$142:$E$203,2,FALSE),0) -> 0 | AF79: =IFERROR(VLOOKUP(B79,OBJECTIFS!$H$142:$J$203,2,FALSE),0) -> 0 | AG79: =IFERROR(VLOOKUP(B79,OBJECTIFS!$F$208:$H$269,3,FALSE),0) -> 0 | AI79: =IFERROR(SUM(AE79:AG79,AC79,Z79,X79),"") -> 0 | AK79: =IFERROR(IF(OR(Q79>=2,R79>=8,AND(Q79=1,R79>=4)),0,IF(OR(AND(Q79=1,R79<4),AND(Q79=0,R79>=4,R79<8)),0.5,1))*N79*(V79-U79)/V79,"") -> 0 | AL79: =IF(AM79="","","è") | AM79: =IF(AK79=0,"",IF(AK79>=MAX($AK$9:$AK$78),A79,""))
Z80: =IF(SUM(Z9:Z79)=SUM(OBJECTIFS!D76:E137),"OK","ALERTE") -> OK | AB80: =IF(SUM(AB9:AB79)=SUM(OBJECTIFS!I76:J137),"OK","ALERTE") -> OK | AE80: =IF(SUM(AE9:AE79)=SUM(OBJECTIFS!D142:E203),"OK","ALERTE") -> OK | AF80: =IF(SUM(AF9:AF79)=SUM(OBJECTIFS!I142:J203),"OK","ALERTE") -> OK | AG80: =IF(SUM(AG9:AG79)=SUM(OBJECTIFS!H208:H269),"OK","ALERTE") -> OK
Z81: Prime moyenne | AG81: Projet | AI81: =IFERROR(AVERAGE($AI$9:$AI$79),"") -> 0
AG82: Débutant | AI82: =IFERROR(SUMIF($F$9:$F$79,AG82,$AI$9:$AI$79)/COUNTIF($F$9:$F$79,AG82),"")
AG83: Confirmé | AI83: =IFERROR(SUMIF($F$9:$F$79,AG83,$AI$9:$AI$79)/COUNTIF($F$9:$F$79,AG83),"")
AG84: Sénior | AI84: =IFERROR(SUMIF($F$9:$F$79,AG84,$AI$9:$AI$79)/COUNTIF($F$9:$F$79,AG84),"")
Z85: Montant total de la prime | AI85: =SUM(AI9:AI79) -> 0
AI86: =IFERROR(SUMIF($E$9:$E$78,#REF!,$AI$9:$AI$79)/COUNTIF($E$9:$E$78,#REF!),"")

Sheet OBJECTIFS
B1: Auteur EG:
B2: Date émission EG:
D4: Nb de points | E4: 100 | J4: MALUS
E5: =+E8 -> CA | F5: =+F8 -> 0 | G5: =+G8 -> 0 | H5: =+H8 -> Note qualité | I5: =+I8 -> 0 | J5: =+J8 -> 0
A6: =B6 -> PVCP NL APSO | B6: =IF($C$45=0,"",$C$45) -> PVCP NL APSO | C6: Statut | D6: Prime (Montant Brut) | E6: Objectifs / Indicateurs / Statuts
A7: =B6 -> PVCP NL APSO | E7: Productivité | H7: Qualité | J7: Sat Client
A8: =B6 -> PVCP NL APSO | E8: =IFERROR(VLOOKUP($B6,Matrice,3,FALSE),"") -> CA | F8: =IFERROR(VLOOKUP($B6,Matrice,4,FALSE),"") -> 0 | G8: =IFERROR(VLOOKUP($B6,Matrice,5,FALSE),"") -> 0 | H8: =IFERROR(VLOOKUP($B6,Matrice,6,FALSE),"") -> Note qualité | I8: =IFERROR(VLOOKUP($B6,Matrice,7,FALSE),"") -> 0 | J8: =IFERROR(VLOOKUP($B6,Matrice,8,FALSE),"") -> 0
A9: =B6 -> PVCP NL APSO | C9: Débutant
A10: =B6 -> PVCP NL APSO | C10: Confirmé
A11: =B6 -> PVCP NL APSO | C11: Sénior
A13: =B13 | B13: =IF($C$46=0,"",$C$46) | C13: =C6 -> Statut | D13: =D6 -> Prime (Montant Brut) | E13: Objectifs / Indicateurs / Statuts
A14: =B13 | E14: Productivité | H14: Qualité | J14: Sat Client
A15: =B13 | E15: =IFERROR(VLOOKUP($B13,Matrice,3,FALSE),"") | F15: =IFERROR(VLOOKUP($B13,Matrice,4,FALSE),"") | G15: =IFERROR(VLOOKUP($B13,Matrice,5,FALSE),"") | H15: =IFERROR(VLOOKUP($B13,Matrice,6,FALSE),"") | I15: =IFERROR(VLOOKUP($B13,Matrice,7,FALSE),"") | J15: =IFERROR(VLOOKUP($B13,Matrice,8,FALSE),"")
A16: =B13 | C16: =C9 -> Débutant | D16: 1200 | J16: 0
A17: =B13 | C17: =C10 -> Confirmé | D17: 1200 | J17: 0
A18: =B13 | C18: =C11 -> Sénior | D18: 1200 | J18: 0
A20: =B20 | B20: =IF($C$47=0,"",$C$47) | C20: =C6 -> Statut | D20: =D6 -> Prime (Montant Brut) | E20: Objectifs / Indicateurs / Statuts
A21: =B20 | E21: Productivité | H21: Qualité | J21: Sat Client
A22: =B20 | E22: =IFERROR(VLOOKUP($B20,Matrice,3,FALSE),"") | F22: =IFERROR(VLOOKUP($B20,Matrice,4,FALSE),"") | G22: =IFERROR(VLOOKUP($B20,Matrice,5,FALSE),"") | H22: =IFERROR(VLOOKUP($B20,Matrice,6,FALSE),"") | I22: =IFERROR(VLOOKUP($B20,Matrice,7,FALSE),"") | J22: =IFERROR(VLOOKUP($B20,Matrice,8,FALSE),"")
A23: =B20 | C23: =C9 -> Débutant | D23: 1200 | J23: 0
A24: =B20 | C24: =C10 -> Confirmé | D24: 960 | J24: 0
A25: =B20 | C25: =C11 -> Sénior | D25: 960 | J25: 0
A27: =B27 | B27: =IF($C$48=0,"",$C$48) | C27: =C6 -> Statut | D27: =D6 -> Prime (Montant Brut) | E27: Objectifs / Indicateurs / Statuts
A28: =B27 | E28: Productivité | H28: Qualité | J28: Sat Client
A29: =B27 | E29: =IFERROR(VLOOKUP($B27,Matrice,3,FALSE),"") | F29: =IFERROR(VLOOKUP($B27,Matrice,4,FALSE),"") | G29: =IFERROR(VLOOKUP($B27,Matrice,5,FALSE),"") | H29: =IFERROR(VLOOKUP($B27,Matrice,6,FALSE),"") | I29: =IFERROR(VLOOKUP($B27,Matrice,7,FALSE),"") | J29: =IFERROR(VLOOKUP($B27,Matrice,8,FALSE),"")
A30: =B27 | C30: =C9 -> Débutant | D30: 960 | J30: 0
A31: =B27 | C31: =C10 -> Confirmé | D31: 960 | J31: 0
A32: =B27 | C32: =C11 -> Sénior | D32: 960 | J32: 0
A34: =B34 | B34: =IF($C$48=0,"",$C$49) | C34: =C13 -> Statut | D34: =D13 -> Prime (Montant Brut) | E34: Objectifs / Indicateurs / Statuts
A35: =B34 | E35: Productivité | H35: Qualité | J35: Sat Client
A36: =B34 | E36: =IFERROR(VLOOKUP($B34,Matrice,3,FALSE),"") | F36: =IFERROR(VLOOKUP($B34,Matrice,4,FALSE),"") | G36: =IFERROR(VLOOKUP($B34,Matrice,5,FALSE),"") | H36: =IFERROR(VLOOKUP($B34,Matrice,6,FALSE),"") | I36: =IFERROR(VLOOKUP($B34,Matrice,7,FALSE),"") | J36: =IFERROR(VLOOKUP($B34,Matrice,8,FALSE),"")
A37: =B34 | C37: =C16 -> Débutant | D37: 960 | J37: 0
A38: =B34 | C38: =C17 -> Confirmé | D38: 960 | J38: 0
A39: =B34 | C39: =C18 -> Sénior | D39: 1440 | J39: 0
C43: Matrice des indicateurs par typologie d'activité
C45: PVCP NL APSO | E45: CA | H45: Note qualité
E52: Paliers VS % Points
E54: Min | G54: Objectif | I54: Max
E56: 0.85 | G56: 0.9 | I56: 1
F58: Palier 1 | H58: Palier 2 | J58: Palier 3
...
